[2025-02-08T17:51:40.307+0000] {processor.py:186} INFO - Started process (PID=11406) to work on /opt/airflow/dags/pools.py
[2025-02-08T17:51:40.310+0000] {processor.py:914} INFO - Processing file /opt/airflow/dags/pools.py for tasks to queue
[2025-02-08T17:51:40.314+0000] {logging_mixin.py:190} INFO - [2025-02-08T17:51:40.313+0000] {dagbag.py:588} INFO - Filling up the DagBag from /opt/airflow/dags/pools.py
[2025-02-08T17:51:40.507+0000] {logging_mixin.py:190} INFO - [2025-02-08T17:51:40.459+0000] {dagbag.py:387} ERROR - Failed to import: /opt/airflow/dags/pools.py
Traceback (most recent call last):
  File "/home/airflow/.local/lib/python3.12/site-packages/airflow/models/dagbag.py", line 383, in parse
    loader.exec_module(new_module)
  File "<frozen importlib._bootstrap_external>", line 999, in exec_module
  File "<frozen importlib._bootstrap>", line 488, in _call_with_frames_removed
  File "/opt/airflow/dags/pools.py", line 16, in <module>
    create_table = PostgresOperator(
                   ^^^^^^^^^^^^^^^^^
  File "/home/airflow/.local/lib/python3.12/site-packages/airflow/models/baseoperator.py", line 506, in apply_defaults
    result = func(self, **kwargs, default_args=default_args)
             ^^^^^^^^^^^^^^^^^^^^^^^^^^^^^^^^^^^^^^^^^^^^^^^
  File "/home/airflow/.local/lib/python3.12/site-packages/airflow/providers/postgres/operators/postgres.py", line 87, in __init__
    super().__init__(conn_id=postgres_conn_id, **kwargs)
  File "/home/airflow/.local/lib/python3.12/site-packages/airflow/models/baseoperator.py", line 489, in apply_defaults
    raise AirflowException(f"missing keyword argument {missing_args.pop()!r}")
airflow.exceptions.AirflowException: missing keyword argument 'sql'
[2025-02-08T17:51:40.512+0000] {processor.py:927} WARNING - No viable dags retrieved from /opt/airflow/dags/pools.py
[2025-02-08T17:51:40.676+0000] {processor.py:208} INFO - Processing /opt/airflow/dags/pools.py took 0.391 seconds
[2025-02-08T17:52:12.776+0000] {processor.py:186} INFO - Started process (PID=11471) to work on /opt/airflow/dags/pools.py
[2025-02-08T17:52:12.794+0000] {processor.py:914} INFO - Processing file /opt/airflow/dags/pools.py for tasks to queue
[2025-02-08T17:52:12.798+0000] {logging_mixin.py:190} INFO - [2025-02-08T17:52:12.797+0000] {dagbag.py:588} INFO - Filling up the DagBag from /opt/airflow/dags/pools.py
[2025-02-08T17:52:13.077+0000] {logging_mixin.py:190} INFO - [2025-02-08T17:52:12.992+0000] {dagbag.py:387} ERROR - Failed to import: /opt/airflow/dags/pools.py
Traceback (most recent call last):
  File "/home/airflow/.local/lib/python3.12/site-packages/airflow/models/dagbag.py", line 383, in parse
    loader.exec_module(new_module)
  File "<frozen importlib._bootstrap_external>", line 999, in exec_module
  File "<frozen importlib._bootstrap>", line 488, in _call_with_frames_removed
  File "/opt/airflow/dags/pools.py", line 16, in <module>
    create_table = PostgresOperator(
                   ^^^^^^^^^^^^^^^^^
  File "/home/airflow/.local/lib/python3.12/site-packages/airflow/models/baseoperator.py", line 506, in apply_defaults
    result = func(self, **kwargs, default_args=default_args)
             ^^^^^^^^^^^^^^^^^^^^^^^^^^^^^^^^^^^^^^^^^^^^^^^
  File "/home/airflow/.local/lib/python3.12/site-packages/airflow/providers/postgres/operators/postgres.py", line 87, in __init__
    super().__init__(conn_id=postgres_conn_id, **kwargs)
  File "/home/airflow/.local/lib/python3.12/site-packages/airflow/models/baseoperator.py", line 489, in apply_defaults
    raise AirflowException(f"missing keyword argument {missing_args.pop()!r}")
airflow.exceptions.AirflowException: missing keyword argument 'sql'
[2025-02-08T17:52:13.085+0000] {processor.py:927} WARNING - No viable dags retrieved from /opt/airflow/dags/pools.py
[2025-02-08T17:52:13.193+0000] {processor.py:208} INFO - Processing /opt/airflow/dags/pools.py took 0.444 seconds
[2025-02-08T17:52:49.255+0000] {processor.py:186} INFO - Started process (PID=11543) to work on /opt/airflow/dags/pools.py
[2025-02-08T17:52:49.279+0000] {processor.py:914} INFO - Processing file /opt/airflow/dags/pools.py for tasks to queue
[2025-02-08T17:52:49.300+0000] {logging_mixin.py:190} INFO - [2025-02-08T17:52:49.299+0000] {dagbag.py:588} INFO - Filling up the DagBag from /opt/airflow/dags/pools.py
[2025-02-08T17:52:49.884+0000] {logging_mixin.py:190} INFO - [2025-02-08T17:52:49.828+0000] {dagbag.py:387} ERROR - Failed to import: /opt/airflow/dags/pools.py
Traceback (most recent call last):
  File "/home/airflow/.local/lib/python3.12/site-packages/airflow/models/dagbag.py", line 383, in parse
    loader.exec_module(new_module)
  File "<frozen importlib._bootstrap_external>", line 999, in exec_module
  File "<frozen importlib._bootstrap>", line 488, in _call_with_frames_removed
  File "/opt/airflow/dags/pools.py", line 16, in <module>
    create_table = PostgresOperator(
                   ^^^^^^^^^^^^^^^^^
  File "/home/airflow/.local/lib/python3.12/site-packages/airflow/models/baseoperator.py", line 506, in apply_defaults
    result = func(self, **kwargs, default_args=default_args)
             ^^^^^^^^^^^^^^^^^^^^^^^^^^^^^^^^^^^^^^^^^^^^^^^
  File "/home/airflow/.local/lib/python3.12/site-packages/airflow/providers/postgres/operators/postgres.py", line 87, in __init__
    super().__init__(conn_id=postgres_conn_id, **kwargs)
  File "/home/airflow/.local/lib/python3.12/site-packages/airflow/models/baseoperator.py", line 489, in apply_defaults
    raise AirflowException(f"missing keyword argument {missing_args.pop()!r}")
airflow.exceptions.AirflowException: missing keyword argument 'sql'
[2025-02-08T17:52:49.897+0000] {processor.py:927} WARNING - No viable dags retrieved from /opt/airflow/dags/pools.py
[2025-02-08T17:52:50.319+0000] {processor.py:208} INFO - Processing /opt/airflow/dags/pools.py took 1.113 seconds
[2025-02-08T17:53:20.616+0000] {processor.py:186} INFO - Started process (PID=11610) to work on /opt/airflow/dags/pools.py
[2025-02-08T17:53:20.629+0000] {processor.py:914} INFO - Processing file /opt/airflow/dags/pools.py for tasks to queue
[2025-02-08T17:53:20.633+0000] {logging_mixin.py:190} INFO - [2025-02-08T17:53:20.632+0000] {dagbag.py:588} INFO - Filling up the DagBag from /opt/airflow/dags/pools.py
[2025-02-08T17:53:20.768+0000] {logging_mixin.py:190} INFO - [2025-02-08T17:53:20.733+0000] {dagbag.py:387} ERROR - Failed to import: /opt/airflow/dags/pools.py
Traceback (most recent call last):
  File "/home/airflow/.local/lib/python3.12/site-packages/airflow/models/dagbag.py", line 383, in parse
    loader.exec_module(new_module)
  File "<frozen importlib._bootstrap_external>", line 999, in exec_module
  File "<frozen importlib._bootstrap>", line 488, in _call_with_frames_removed
  File "/opt/airflow/dags/pools.py", line 16, in <module>
    create_table = PostgresOperator(
                   ^^^^^^^^^^^^^^^^^
  File "/home/airflow/.local/lib/python3.12/site-packages/airflow/models/baseoperator.py", line 506, in apply_defaults
    result = func(self, **kwargs, default_args=default_args)
             ^^^^^^^^^^^^^^^^^^^^^^^^^^^^^^^^^^^^^^^^^^^^^^^
  File "/home/airflow/.local/lib/python3.12/site-packages/airflow/providers/postgres/operators/postgres.py", line 87, in __init__
    super().__init__(conn_id=postgres_conn_id, **kwargs)
  File "/home/airflow/.local/lib/python3.12/site-packages/airflow/models/baseoperator.py", line 489, in apply_defaults
    raise AirflowException(f"missing keyword argument {missing_args.pop()!r}")
airflow.exceptions.AirflowException: missing keyword argument 'sql'
[2025-02-08T17:53:20.772+0000] {processor.py:927} WARNING - No viable dags retrieved from /opt/airflow/dags/pools.py
[2025-02-08T17:53:20.882+0000] {processor.py:208} INFO - Processing /opt/airflow/dags/pools.py took 0.315 seconds
[2025-02-08T17:53:51.418+0000] {processor.py:186} INFO - Started process (PID=11666) to work on /opt/airflow/dags/pools.py
[2025-02-08T17:53:51.435+0000] {processor.py:914} INFO - Processing file /opt/airflow/dags/pools.py for tasks to queue
[2025-02-08T17:53:51.445+0000] {logging_mixin.py:190} INFO - [2025-02-08T17:53:51.445+0000] {dagbag.py:588} INFO - Filling up the DagBag from /opt/airflow/dags/pools.py
[2025-02-08T17:53:51.493+0000] {logging_mixin.py:190} INFO - [2025-02-08T17:53:51.481+0000] {dagbag.py:387} ERROR - Failed to import: /opt/airflow/dags/pools.py
Traceback (most recent call last):
  File "/home/airflow/.local/lib/python3.12/site-packages/airflow/models/dagbag.py", line 383, in parse
    loader.exec_module(new_module)
  File "<frozen importlib._bootstrap_external>", line 999, in exec_module
  File "<frozen importlib._bootstrap>", line 488, in _call_with_frames_removed
  File "/opt/airflow/dags/pools.py", line 16, in <module>
    create_table = PostgresOperator(
                   ^^^^^^^^^^^^^^^^^
  File "/home/airflow/.local/lib/python3.12/site-packages/airflow/models/baseoperator.py", line 506, in apply_defaults
    result = func(self, **kwargs, default_args=default_args)
             ^^^^^^^^^^^^^^^^^^^^^^^^^^^^^^^^^^^^^^^^^^^^^^^
  File "/home/airflow/.local/lib/python3.12/site-packages/airflow/providers/postgres/operators/postgres.py", line 87, in __init__
    super().__init__(conn_id=postgres_conn_id, **kwargs)
  File "/home/airflow/.local/lib/python3.12/site-packages/airflow/models/baseoperator.py", line 489, in apply_defaults
    raise AirflowException(f"missing keyword argument {missing_args.pop()!r}")
airflow.exceptions.AirflowException: missing keyword argument 'sql'
[2025-02-08T17:53:51.511+0000] {processor.py:927} WARNING - No viable dags retrieved from /opt/airflow/dags/pools.py
[2025-02-08T17:53:51.581+0000] {processor.py:208} INFO - Processing /opt/airflow/dags/pools.py took 0.196 seconds
[2025-02-08T17:54:26.280+0000] {processor.py:186} INFO - Started process (PID=11731) to work on /opt/airflow/dags/pools.py
[2025-02-08T17:54:26.281+0000] {processor.py:914} INFO - Processing file /opt/airflow/dags/pools.py for tasks to queue
[2025-02-08T17:54:26.285+0000] {logging_mixin.py:190} INFO - [2025-02-08T17:54:26.283+0000] {dagbag.py:588} INFO - Filling up the DagBag from /opt/airflow/dags/pools.py
[2025-02-08T17:54:26.356+0000] {logging_mixin.py:190} INFO - [2025-02-08T17:54:26.321+0000] {dagbag.py:387} ERROR - Failed to import: /opt/airflow/dags/pools.py
Traceback (most recent call last):
  File "/home/airflow/.local/lib/python3.12/site-packages/airflow/models/dagbag.py", line 383, in parse
    loader.exec_module(new_module)
  File "<frozen importlib._bootstrap_external>", line 999, in exec_module
  File "<frozen importlib._bootstrap>", line 488, in _call_with_frames_removed
  File "/opt/airflow/dags/pools.py", line 16, in <module>
    create_table = PostgresOperator(
                   ^^^^^^^^^^^^^^^^^
  File "/home/airflow/.local/lib/python3.12/site-packages/airflow/models/baseoperator.py", line 506, in apply_defaults
    result = func(self, **kwargs, default_args=default_args)
             ^^^^^^^^^^^^^^^^^^^^^^^^^^^^^^^^^^^^^^^^^^^^^^^
  File "/home/airflow/.local/lib/python3.12/site-packages/airflow/providers/postgres/operators/postgres.py", line 87, in __init__
    super().__init__(conn_id=postgres_conn_id, **kwargs)
  File "/home/airflow/.local/lib/python3.12/site-packages/airflow/models/baseoperator.py", line 489, in apply_defaults
    raise AirflowException(f"missing keyword argument {missing_args.pop()!r}")
airflow.exceptions.AirflowException: missing keyword argument 'sql'
[2025-02-08T17:54:26.359+0000] {processor.py:927} WARNING - No viable dags retrieved from /opt/airflow/dags/pools.py
[2025-02-08T17:54:26.429+0000] {processor.py:208} INFO - Processing /opt/airflow/dags/pools.py took 0.163 seconds
[2025-02-08T17:54:57.570+0000] {processor.py:186} INFO - Started process (PID=11795) to work on /opt/airflow/dags/pools.py
[2025-02-08T17:54:57.589+0000] {processor.py:914} INFO - Processing file /opt/airflow/dags/pools.py for tasks to queue
[2025-02-08T17:54:57.663+0000] {logging_mixin.py:190} INFO - [2025-02-08T17:54:57.662+0000] {dagbag.py:588} INFO - Filling up the DagBag from /opt/airflow/dags/pools.py
[2025-02-08T17:54:58.754+0000] {logging_mixin.py:190} INFO - [2025-02-08T17:54:58.737+0000] {dagbag.py:387} ERROR - Failed to import: /opt/airflow/dags/pools.py
Traceback (most recent call last):
  File "/home/airflow/.local/lib/python3.12/site-packages/airflow/models/dagbag.py", line 383, in parse
    loader.exec_module(new_module)
  File "<frozen importlib._bootstrap_external>", line 999, in exec_module
  File "<frozen importlib._bootstrap>", line 488, in _call_with_frames_removed
  File "/opt/airflow/dags/pools.py", line 16, in <module>
    create_table = PostgresOperator(
                   ^^^^^^^^^^^^^^^^^
  File "/home/airflow/.local/lib/python3.12/site-packages/airflow/models/baseoperator.py", line 506, in apply_defaults
    result = func(self, **kwargs, default_args=default_args)
             ^^^^^^^^^^^^^^^^^^^^^^^^^^^^^^^^^^^^^^^^^^^^^^^
  File "/home/airflow/.local/lib/python3.12/site-packages/airflow/providers/postgres/operators/postgres.py", line 87, in __init__
    super().__init__(conn_id=postgres_conn_id, **kwargs)
  File "/home/airflow/.local/lib/python3.12/site-packages/airflow/models/baseoperator.py", line 489, in apply_defaults
    raise AirflowException(f"missing keyword argument {missing_args.pop()!r}")
airflow.exceptions.AirflowException: missing keyword argument 'sql'
[2025-02-08T17:54:58.773+0000] {processor.py:927} WARNING - No viable dags retrieved from /opt/airflow/dags/pools.py
[2025-02-08T17:54:58.904+0000] {processor.py:208} INFO - Processing /opt/airflow/dags/pools.py took 1.389 seconds
[2025-02-08T17:55:29.246+0000] {processor.py:186} INFO - Started process (PID=11862) to work on /opt/airflow/dags/pools.py
[2025-02-08T17:55:29.248+0000] {processor.py:914} INFO - Processing file /opt/airflow/dags/pools.py for tasks to queue
[2025-02-08T17:55:29.252+0000] {logging_mixin.py:190} INFO - [2025-02-08T17:55:29.251+0000] {dagbag.py:588} INFO - Filling up the DagBag from /opt/airflow/dags/pools.py
[2025-02-08T17:55:29.414+0000] {logging_mixin.py:190} INFO - [2025-02-08T17:55:29.325+0000] {dagbag.py:387} ERROR - Failed to import: /opt/airflow/dags/pools.py
Traceback (most recent call last):
  File "/home/airflow/.local/lib/python3.12/site-packages/airflow/models/dagbag.py", line 383, in parse
    loader.exec_module(new_module)
  File "<frozen importlib._bootstrap_external>", line 999, in exec_module
  File "<frozen importlib._bootstrap>", line 488, in _call_with_frames_removed
  File "/opt/airflow/dags/pools.py", line 16, in <module>
    create_table = PostgresOperator(
                   ^^^^^^^^^^^^^^^^^
  File "/home/airflow/.local/lib/python3.12/site-packages/airflow/models/baseoperator.py", line 506, in apply_defaults
    result = func(self, **kwargs, default_args=default_args)
             ^^^^^^^^^^^^^^^^^^^^^^^^^^^^^^^^^^^^^^^^^^^^^^^
  File "/home/airflow/.local/lib/python3.12/site-packages/airflow/providers/postgres/operators/postgres.py", line 87, in __init__
    super().__init__(conn_id=postgres_conn_id, **kwargs)
  File "/home/airflow/.local/lib/python3.12/site-packages/airflow/models/baseoperator.py", line 489, in apply_defaults
    raise AirflowException(f"missing keyword argument {missing_args.pop()!r}")
airflow.exceptions.AirflowException: missing keyword argument 'sql'
[2025-02-08T17:55:29.426+0000] {processor.py:927} WARNING - No viable dags retrieved from /opt/airflow/dags/pools.py
[2025-02-08T17:55:29.530+0000] {processor.py:208} INFO - Processing /opt/airflow/dags/pools.py took 0.303 seconds
[2025-02-08T17:56:37.417+0000] {processor.py:186} INFO - Started process (PID=11932) to work on /opt/airflow/dags/pools.py
[2025-02-08T17:56:37.441+0000] {processor.py:914} INFO - Processing file /opt/airflow/dags/pools.py for tasks to queue
[2025-02-08T17:56:37.461+0000] {logging_mixin.py:190} INFO - [2025-02-08T17:56:37.460+0000] {dagbag.py:588} INFO - Filling up the DagBag from /opt/airflow/dags/pools.py
[2025-02-08T17:56:41.259+0000] {logging_mixin.py:190} INFO - [2025-02-08T17:56:40.578+0000] {dagbag.py:387} ERROR - Failed to import: /opt/airflow/dags/pools.py
Traceback (most recent call last):
  File "/home/airflow/.local/lib/python3.12/site-packages/airflow/models/dagbag.py", line 383, in parse
    loader.exec_module(new_module)
  File "<frozen importlib._bootstrap_external>", line 999, in exec_module
  File "<frozen importlib._bootstrap>", line 488, in _call_with_frames_removed
  File "/opt/airflow/dags/pools.py", line 55, in <module>
    select_values = PostgresOperator(
                    ^^^^^^^^^^^^^^^^^
  File "/home/airflow/.local/lib/python3.12/site-packages/airflow/models/baseoperator.py", line 506, in apply_defaults
    result = func(self, **kwargs, default_args=default_args)
             ^^^^^^^^^^^^^^^^^^^^^^^^^^^^^^^^^^^^^^^^^^^^^^^
  File "/home/airflow/.local/lib/python3.12/site-packages/airflow/providers/postgres/operators/postgres.py", line 87, in __init__
    super().__init__(conn_id=postgres_conn_id, **kwargs)
  File "/home/airflow/.local/lib/python3.12/site-packages/airflow/models/baseoperator.py", line 506, in apply_defaults
    result = func(self, **kwargs, default_args=default_args)
             ^^^^^^^^^^^^^^^^^^^^^^^^^^^^^^^^^^^^^^^^^^^^^^^
  File "/home/airflow/.local/lib/python3.12/site-packages/airflow/providers/common/sql/operators/sql.py", line 244, in __init__
    super().__init__(conn_id=conn_id, database=database, **kwargs)
  File "/home/airflow/.local/lib/python3.12/site-packages/airflow/models/baseoperator.py", line 506, in apply_defaults
    result = func(self, **kwargs, default_args=default_args)
             ^^^^^^^^^^^^^^^^^^^^^^^^^^^^^^^^^^^^^^^^^^^^^^^
  File "/home/airflow/.local/lib/python3.12/site-packages/airflow/providers/common/sql/operators/sql.py", line 142, in __init__
    super().__init__(**kwargs)
  File "/home/airflow/.local/lib/python3.12/site-packages/airflow/models/baseoperator.py", line 506, in apply_defaults
    result = func(self, **kwargs, default_args=default_args)
             ^^^^^^^^^^^^^^^^^^^^^^^^^^^^^^^^^^^^^^^^^^^^^^^
  File "/home/airflow/.local/lib/python3.12/site-packages/airflow/models/baseoperator.py", line 975, in __init__
    task_group.add(self)
  File "/home/airflow/.local/lib/python3.12/site-packages/airflow/utils/task_group.py", line 256, in add
    raise DuplicateTaskIdFound(f"{node_type} id '{key}' has already been added to the DAG")
airflow.exceptions.DuplicateTaskIdFound: Task id 'select_values' has already been added to the DAG
[2025-02-08T17:56:41.343+0000] {processor.py:927} WARNING - No viable dags retrieved from /opt/airflow/dags/pools.py
[2025-02-08T17:56:41.771+0000] {processor.py:208} INFO - Processing /opt/airflow/dags/pools.py took 4.393 seconds
[2025-02-08T17:57:22.223+0000] {processor.py:186} INFO - Started process (PID=11999) to work on /opt/airflow/dags/pools.py
[2025-02-08T17:57:22.230+0000] {processor.py:914} INFO - Processing file /opt/airflow/dags/pools.py for tasks to queue
[2025-02-08T17:57:22.250+0000] {logging_mixin.py:190} INFO - [2025-02-08T17:57:22.248+0000] {dagbag.py:588} INFO - Filling up the DagBag from /opt/airflow/dags/pools.py
[2025-02-08T17:57:22.831+0000] {logging_mixin.py:190} INFO - [2025-02-08T17:57:22.650+0000] {dagbag.py:387} ERROR - Failed to import: /opt/airflow/dags/pools.py
Traceback (most recent call last):
  File "/home/airflow/.local/lib/python3.12/site-packages/airflow/models/dagbag.py", line 383, in parse
    loader.exec_module(new_module)
  File "<frozen importlib._bootstrap_external>", line 999, in exec_module
  File "<frozen importlib._bootstrap>", line 488, in _call_with_frames_removed
  File "/opt/airflow/dags/pools.py", line 55, in <module>
    select_values = PostgresOperator(
                    ^^^^^^^^^^^^^^^^^
  File "/home/airflow/.local/lib/python3.12/site-packages/airflow/models/baseoperator.py", line 506, in apply_defaults
    result = func(self, **kwargs, default_args=default_args)
             ^^^^^^^^^^^^^^^^^^^^^^^^^^^^^^^^^^^^^^^^^^^^^^^
  File "/home/airflow/.local/lib/python3.12/site-packages/airflow/providers/postgres/operators/postgres.py", line 87, in __init__
    super().__init__(conn_id=postgres_conn_id, **kwargs)
  File "/home/airflow/.local/lib/python3.12/site-packages/airflow/models/baseoperator.py", line 506, in apply_defaults
    result = func(self, **kwargs, default_args=default_args)
             ^^^^^^^^^^^^^^^^^^^^^^^^^^^^^^^^^^^^^^^^^^^^^^^
  File "/home/airflow/.local/lib/python3.12/site-packages/airflow/providers/common/sql/operators/sql.py", line 244, in __init__
    super().__init__(conn_id=conn_id, database=database, **kwargs)
  File "/home/airflow/.local/lib/python3.12/site-packages/airflow/models/baseoperator.py", line 506, in apply_defaults
    result = func(self, **kwargs, default_args=default_args)
             ^^^^^^^^^^^^^^^^^^^^^^^^^^^^^^^^^^^^^^^^^^^^^^^
  File "/home/airflow/.local/lib/python3.12/site-packages/airflow/providers/common/sql/operators/sql.py", line 142, in __init__
    super().__init__(**kwargs)
  File "/home/airflow/.local/lib/python3.12/site-packages/airflow/models/baseoperator.py", line 506, in apply_defaults
    result = func(self, **kwargs, default_args=default_args)
             ^^^^^^^^^^^^^^^^^^^^^^^^^^^^^^^^^^^^^^^^^^^^^^^
  File "/home/airflow/.local/lib/python3.12/site-packages/airflow/models/baseoperator.py", line 975, in __init__
    task_group.add(self)
  File "/home/airflow/.local/lib/python3.12/site-packages/airflow/utils/task_group.py", line 256, in add
    raise DuplicateTaskIdFound(f"{node_type} id '{key}' has already been added to the DAG")
airflow.exceptions.DuplicateTaskIdFound: Task id 'select_values' has already been added to the DAG
[2025-02-08T17:57:22.848+0000] {processor.py:927} WARNING - No viable dags retrieved from /opt/airflow/dags/pools.py
[2025-02-08T17:57:23.033+0000] {processor.py:208} INFO - Processing /opt/airflow/dags/pools.py took 0.836 seconds
[2025-02-08T17:57:54.106+0000] {processor.py:186} INFO - Started process (PID=12066) to work on /opt/airflow/dags/pools.py
[2025-02-08T17:57:54.112+0000] {processor.py:914} INFO - Processing file /opt/airflow/dags/pools.py for tasks to queue
[2025-02-08T17:57:54.117+0000] {logging_mixin.py:190} INFO - [2025-02-08T17:57:54.116+0000] {dagbag.py:588} INFO - Filling up the DagBag from /opt/airflow/dags/pools.py
[2025-02-08T17:57:54.200+0000] {logging_mixin.py:190} INFO - [2025-02-08T17:57:54.179+0000] {dagbag.py:387} ERROR - Failed to import: /opt/airflow/dags/pools.py
Traceback (most recent call last):
  File "/home/airflow/.local/lib/python3.12/site-packages/airflow/models/dagbag.py", line 383, in parse
    loader.exec_module(new_module)
  File "<frozen importlib._bootstrap_external>", line 999, in exec_module
  File "<frozen importlib._bootstrap>", line 488, in _call_with_frames_removed
  File "/opt/airflow/dags/pools.py", line 55, in <module>
    select_values = PostgresOperator(
                    ^^^^^^^^^^^^^^^^^
  File "/home/airflow/.local/lib/python3.12/site-packages/airflow/models/baseoperator.py", line 506, in apply_defaults
    result = func(self, **kwargs, default_args=default_args)
             ^^^^^^^^^^^^^^^^^^^^^^^^^^^^^^^^^^^^^^^^^^^^^^^
  File "/home/airflow/.local/lib/python3.12/site-packages/airflow/providers/postgres/operators/postgres.py", line 87, in __init__
    super().__init__(conn_id=postgres_conn_id, **kwargs)
  File "/home/airflow/.local/lib/python3.12/site-packages/airflow/models/baseoperator.py", line 506, in apply_defaults
    result = func(self, **kwargs, default_args=default_args)
             ^^^^^^^^^^^^^^^^^^^^^^^^^^^^^^^^^^^^^^^^^^^^^^^
  File "/home/airflow/.local/lib/python3.12/site-packages/airflow/providers/common/sql/operators/sql.py", line 244, in __init__
    super().__init__(conn_id=conn_id, database=database, **kwargs)
  File "/home/airflow/.local/lib/python3.12/site-packages/airflow/models/baseoperator.py", line 506, in apply_defaults
    result = func(self, **kwargs, default_args=default_args)
             ^^^^^^^^^^^^^^^^^^^^^^^^^^^^^^^^^^^^^^^^^^^^^^^
  File "/home/airflow/.local/lib/python3.12/site-packages/airflow/providers/common/sql/operators/sql.py", line 142, in __init__
    super().__init__(**kwargs)
  File "/home/airflow/.local/lib/python3.12/site-packages/airflow/models/baseoperator.py", line 506, in apply_defaults
    result = func(self, **kwargs, default_args=default_args)
             ^^^^^^^^^^^^^^^^^^^^^^^^^^^^^^^^^^^^^^^^^^^^^^^
  File "/home/airflow/.local/lib/python3.12/site-packages/airflow/models/baseoperator.py", line 975, in __init__
    task_group.add(self)
  File "/home/airflow/.local/lib/python3.12/site-packages/airflow/utils/task_group.py", line 256, in add
    raise DuplicateTaskIdFound(f"{node_type} id '{key}' has already been added to the DAG")
airflow.exceptions.DuplicateTaskIdFound: Task id 'select_values' has already been added to the DAG
[2025-02-08T17:57:54.212+0000] {processor.py:927} WARNING - No viable dags retrieved from /opt/airflow/dags/pools.py
[2025-02-08T17:57:54.280+0000] {processor.py:208} INFO - Processing /opt/airflow/dags/pools.py took 0.195 seconds
[2025-02-08T17:58:25.340+0000] {processor.py:186} INFO - Started process (PID=12131) to work on /opt/airflow/dags/pools.py
[2025-02-08T17:58:25.409+0000] {processor.py:914} INFO - Processing file /opt/airflow/dags/pools.py for tasks to queue
[2025-02-08T17:58:25.423+0000] {logging_mixin.py:190} INFO - [2025-02-08T17:58:25.422+0000] {dagbag.py:588} INFO - Filling up the DagBag from /opt/airflow/dags/pools.py
[2025-02-08T17:58:25.878+0000] {logging_mixin.py:190} INFO - [2025-02-08T17:58:25.828+0000] {dagbag.py:387} ERROR - Failed to import: /opt/airflow/dags/pools.py
Traceback (most recent call last):
  File "/home/airflow/.local/lib/python3.12/site-packages/airflow/models/dagbag.py", line 383, in parse
    loader.exec_module(new_module)
  File "<frozen importlib._bootstrap_external>", line 999, in exec_module
  File "<frozen importlib._bootstrap>", line 488, in _call_with_frames_removed
  File "/opt/airflow/dags/pools.py", line 55, in <module>
    select_values = PostgresOperator(
                    ^^^^^^^^^^^^^^^^^
  File "/home/airflow/.local/lib/python3.12/site-packages/airflow/models/baseoperator.py", line 506, in apply_defaults
    result = func(self, **kwargs, default_args=default_args)
             ^^^^^^^^^^^^^^^^^^^^^^^^^^^^^^^^^^^^^^^^^^^^^^^
  File "/home/airflow/.local/lib/python3.12/site-packages/airflow/providers/postgres/operators/postgres.py", line 87, in __init__
    super().__init__(conn_id=postgres_conn_id, **kwargs)
  File "/home/airflow/.local/lib/python3.12/site-packages/airflow/models/baseoperator.py", line 506, in apply_defaults
    result = func(self, **kwargs, default_args=default_args)
             ^^^^^^^^^^^^^^^^^^^^^^^^^^^^^^^^^^^^^^^^^^^^^^^
  File "/home/airflow/.local/lib/python3.12/site-packages/airflow/providers/common/sql/operators/sql.py", line 244, in __init__
    super().__init__(conn_id=conn_id, database=database, **kwargs)
  File "/home/airflow/.local/lib/python3.12/site-packages/airflow/models/baseoperator.py", line 506, in apply_defaults
    result = func(self, **kwargs, default_args=default_args)
             ^^^^^^^^^^^^^^^^^^^^^^^^^^^^^^^^^^^^^^^^^^^^^^^
  File "/home/airflow/.local/lib/python3.12/site-packages/airflow/providers/common/sql/operators/sql.py", line 142, in __init__
    super().__init__(**kwargs)
  File "/home/airflow/.local/lib/python3.12/site-packages/airflow/models/baseoperator.py", line 506, in apply_defaults
    result = func(self, **kwargs, default_args=default_args)
             ^^^^^^^^^^^^^^^^^^^^^^^^^^^^^^^^^^^^^^^^^^^^^^^
  File "/home/airflow/.local/lib/python3.12/site-packages/airflow/models/baseoperator.py", line 975, in __init__
    task_group.add(self)
  File "/home/airflow/.local/lib/python3.12/site-packages/airflow/utils/task_group.py", line 256, in add
    raise DuplicateTaskIdFound(f"{node_type} id '{key}' has already been added to the DAG")
airflow.exceptions.DuplicateTaskIdFound: Task id 'select_values' has already been added to the DAG
[2025-02-08T17:58:25.891+0000] {processor.py:927} WARNING - No viable dags retrieved from /opt/airflow/dags/pools.py
[2025-02-08T17:58:26.002+0000] {processor.py:208} INFO - Processing /opt/airflow/dags/pools.py took 0.719 seconds
[2025-02-08T17:59:22.479+0000] {processor.py:186} INFO - Started process (PID=12197) to work on /opt/airflow/dags/pools.py
[2025-02-08T17:59:22.494+0000] {processor.py:914} INFO - Processing file /opt/airflow/dags/pools.py for tasks to queue
[2025-02-08T17:59:22.504+0000] {logging_mixin.py:190} INFO - [2025-02-08T17:59:22.503+0000] {dagbag.py:588} INFO - Filling up the DagBag from /opt/airflow/dags/pools.py
[2025-02-08T17:59:22.605+0000] {logging_mixin.py:190} INFO - [2025-02-08T17:59:22.566+0000] {dagbag.py:387} ERROR - Failed to import: /opt/airflow/dags/pools.py
Traceback (most recent call last):
  File "/home/airflow/.local/lib/python3.12/site-packages/airflow/models/dagbag.py", line 383, in parse
    loader.exec_module(new_module)
  File "<frozen importlib._bootstrap_external>", line 999, in exec_module
  File "<frozen importlib._bootstrap>", line 488, in _call_with_frames_removed
  File "/opt/airflow/dags/pools.py", line 55, in <module>
    select_values = PostgresOperator(
                    ^^^^^^^^^^^^^^^^^
  File "/home/airflow/.local/lib/python3.12/site-packages/airflow/models/baseoperator.py", line 506, in apply_defaults
    result = func(self, **kwargs, default_args=default_args)
             ^^^^^^^^^^^^^^^^^^^^^^^^^^^^^^^^^^^^^^^^^^^^^^^
  File "/home/airflow/.local/lib/python3.12/site-packages/airflow/providers/postgres/operators/postgres.py", line 87, in __init__
    super().__init__(conn_id=postgres_conn_id, **kwargs)
  File "/home/airflow/.local/lib/python3.12/site-packages/airflow/models/baseoperator.py", line 506, in apply_defaults
    result = func(self, **kwargs, default_args=default_args)
             ^^^^^^^^^^^^^^^^^^^^^^^^^^^^^^^^^^^^^^^^^^^^^^^
  File "/home/airflow/.local/lib/python3.12/site-packages/airflow/providers/common/sql/operators/sql.py", line 244, in __init__
    super().__init__(conn_id=conn_id, database=database, **kwargs)
  File "/home/airflow/.local/lib/python3.12/site-packages/airflow/models/baseoperator.py", line 506, in apply_defaults
    result = func(self, **kwargs, default_args=default_args)
             ^^^^^^^^^^^^^^^^^^^^^^^^^^^^^^^^^^^^^^^^^^^^^^^
  File "/home/airflow/.local/lib/python3.12/site-packages/airflow/providers/common/sql/operators/sql.py", line 142, in __init__
    super().__init__(**kwargs)
  File "/home/airflow/.local/lib/python3.12/site-packages/airflow/models/baseoperator.py", line 506, in apply_defaults
    result = func(self, **kwargs, default_args=default_args)
             ^^^^^^^^^^^^^^^^^^^^^^^^^^^^^^^^^^^^^^^^^^^^^^^
  File "/home/airflow/.local/lib/python3.12/site-packages/airflow/models/baseoperator.py", line 975, in __init__
    task_group.add(self)
  File "/home/airflow/.local/lib/python3.12/site-packages/airflow/utils/task_group.py", line 256, in add
    raise DuplicateTaskIdFound(f"{node_type} id '{key}' has already been added to the DAG")
airflow.exceptions.DuplicateTaskIdFound: Task id 'select_values' has already been added to the DAG
[2025-02-08T17:59:22.613+0000] {processor.py:927} WARNING - No viable dags retrieved from /opt/airflow/dags/pools.py
[2025-02-08T17:59:22.734+0000] {processor.py:208} INFO - Processing /opt/airflow/dags/pools.py took 0.286 seconds
[2025-02-08T17:59:57.096+0000] {processor.py:186} INFO - Started process (PID=12234) to work on /opt/airflow/dags/pools.py
[2025-02-08T17:59:57.112+0000] {processor.py:914} INFO - Processing file /opt/airflow/dags/pools.py for tasks to queue
[2025-02-08T17:59:57.124+0000] {logging_mixin.py:190} INFO - [2025-02-08T17:59:57.123+0000] {dagbag.py:588} INFO - Filling up the DagBag from /opt/airflow/dags/pools.py
[2025-02-08T17:59:57.425+0000] {logging_mixin.py:190} INFO - [2025-02-08T17:59:57.308+0000] {dagbag.py:387} ERROR - Failed to import: /opt/airflow/dags/pools.py
Traceback (most recent call last):
  File "/home/airflow/.local/lib/python3.12/site-packages/airflow/models/dagbag.py", line 383, in parse
    loader.exec_module(new_module)
  File "<frozen importlib._bootstrap_external>", line 999, in exec_module
  File "<frozen importlib._bootstrap>", line 488, in _call_with_frames_removed
  File "/opt/airflow/dags/pools.py", line 55, in <module>
    select_values = PostgresOperator(
                    ^^^^^^^^^^^^^^^^^
  File "/home/airflow/.local/lib/python3.12/site-packages/airflow/models/baseoperator.py", line 506, in apply_defaults
    result = func(self, **kwargs, default_args=default_args)
             ^^^^^^^^^^^^^^^^^^^^^^^^^^^^^^^^^^^^^^^^^^^^^^^
  File "/home/airflow/.local/lib/python3.12/site-packages/airflow/providers/postgres/operators/postgres.py", line 87, in __init__
    super().__init__(conn_id=postgres_conn_id, **kwargs)
  File "/home/airflow/.local/lib/python3.12/site-packages/airflow/models/baseoperator.py", line 506, in apply_defaults
    result = func(self, **kwargs, default_args=default_args)
             ^^^^^^^^^^^^^^^^^^^^^^^^^^^^^^^^^^^^^^^^^^^^^^^
  File "/home/airflow/.local/lib/python3.12/site-packages/airflow/providers/common/sql/operators/sql.py", line 244, in __init__
    super().__init__(conn_id=conn_id, database=database, **kwargs)
  File "/home/airflow/.local/lib/python3.12/site-packages/airflow/models/baseoperator.py", line 506, in apply_defaults
    result = func(self, **kwargs, default_args=default_args)
             ^^^^^^^^^^^^^^^^^^^^^^^^^^^^^^^^^^^^^^^^^^^^^^^
  File "/home/airflow/.local/lib/python3.12/site-packages/airflow/providers/common/sql/operators/sql.py", line 142, in __init__
    super().__init__(**kwargs)
  File "/home/airflow/.local/lib/python3.12/site-packages/airflow/models/baseoperator.py", line 506, in apply_defaults
    result = func(self, **kwargs, default_args=default_args)
             ^^^^^^^^^^^^^^^^^^^^^^^^^^^^^^^^^^^^^^^^^^^^^^^
  File "/home/airflow/.local/lib/python3.12/site-packages/airflow/models/baseoperator.py", line 975, in __init__
    task_group.add(self)
  File "/home/airflow/.local/lib/python3.12/site-packages/airflow/utils/task_group.py", line 256, in add
    raise DuplicateTaskIdFound(f"{node_type} id '{key}' has already been added to the DAG")
airflow.exceptions.DuplicateTaskIdFound: Task id 'select_values' has already been added to the DAG
[2025-02-08T17:59:57.431+0000] {processor.py:927} WARNING - No viable dags retrieved from /opt/airflow/dags/pools.py
[2025-02-08T17:59:57.555+0000] {processor.py:208} INFO - Processing /opt/airflow/dags/pools.py took 0.513 seconds
[2025-02-08T18:00:26.521+0000] {processor.py:186} INFO - Started process (PID=12278) to work on /opt/airflow/dags/pools.py
[2025-02-08T18:00:26.523+0000] {processor.py:914} INFO - Processing file /opt/airflow/dags/pools.py for tasks to queue
[2025-02-08T18:00:26.528+0000] {logging_mixin.py:190} INFO - [2025-02-08T18:00:26.527+0000] {dagbag.py:588} INFO - Filling up the DagBag from /opt/airflow/dags/pools.py
[2025-02-08T18:00:26.608+0000] {logging_mixin.py:190} INFO - [2025-02-08T18:00:26.597+0000] {dagbag.py:387} ERROR - Failed to import: /opt/airflow/dags/pools.py
Traceback (most recent call last):
  File "/home/airflow/.local/lib/python3.12/site-packages/airflow/models/dagbag.py", line 383, in parse
    loader.exec_module(new_module)
  File "<frozen importlib._bootstrap_external>", line 999, in exec_module
  File "<frozen importlib._bootstrap>", line 488, in _call_with_frames_removed
  File "/opt/airflow/dags/pools.py", line 58, in <module>
    select_values = PostgresOperator(
                    ^^^^^^^^^^^^^^^^^
  File "/home/airflow/.local/lib/python3.12/site-packages/airflow/models/baseoperator.py", line 506, in apply_defaults
    result = func(self, **kwargs, default_args=default_args)
             ^^^^^^^^^^^^^^^^^^^^^^^^^^^^^^^^^^^^^^^^^^^^^^^
  File "/home/airflow/.local/lib/python3.12/site-packages/airflow/providers/postgres/operators/postgres.py", line 87, in __init__
    super().__init__(conn_id=postgres_conn_id, **kwargs)
  File "/home/airflow/.local/lib/python3.12/site-packages/airflow/models/baseoperator.py", line 506, in apply_defaults
    result = func(self, **kwargs, default_args=default_args)
             ^^^^^^^^^^^^^^^^^^^^^^^^^^^^^^^^^^^^^^^^^^^^^^^
  File "/home/airflow/.local/lib/python3.12/site-packages/airflow/providers/common/sql/operators/sql.py", line 244, in __init__
    super().__init__(conn_id=conn_id, database=database, **kwargs)
  File "/home/airflow/.local/lib/python3.12/site-packages/airflow/models/baseoperator.py", line 506, in apply_defaults
    result = func(self, **kwargs, default_args=default_args)
             ^^^^^^^^^^^^^^^^^^^^^^^^^^^^^^^^^^^^^^^^^^^^^^^
  File "/home/airflow/.local/lib/python3.12/site-packages/airflow/providers/common/sql/operators/sql.py", line 142, in __init__
    super().__init__(**kwargs)
  File "/home/airflow/.local/lib/python3.12/site-packages/airflow/models/baseoperator.py", line 506, in apply_defaults
    result = func(self, **kwargs, default_args=default_args)
             ^^^^^^^^^^^^^^^^^^^^^^^^^^^^^^^^^^^^^^^^^^^^^^^
  File "/home/airflow/.local/lib/python3.12/site-packages/airflow/models/baseoperator.py", line 975, in __init__
    task_group.add(self)
  File "/home/airflow/.local/lib/python3.12/site-packages/airflow/utils/task_group.py", line 256, in add
    raise DuplicateTaskIdFound(f"{node_type} id '{key}' has already been added to the DAG")
airflow.exceptions.DuplicateTaskIdFound: Task id 'select_values' has already been added to the DAG
[2025-02-08T18:00:26.612+0000] {processor.py:927} WARNING - No viable dags retrieved from /opt/airflow/dags/pools.py
[2025-02-08T18:00:26.684+0000] {processor.py:208} INFO - Processing /opt/airflow/dags/pools.py took 0.180 seconds
[2025-02-08T18:00:41.990+0000] {processor.py:186} INFO - Started process (PID=12304) to work on /opt/airflow/dags/pools.py
[2025-02-08T18:00:42.005+0000] {processor.py:914} INFO - Processing file /opt/airflow/dags/pools.py for tasks to queue
[2025-02-08T18:00:42.010+0000] {logging_mixin.py:190} INFO - [2025-02-08T18:00:42.008+0000] {dagbag.py:588} INFO - Filling up the DagBag from /opt/airflow/dags/pools.py
[2025-02-08T18:00:42.150+0000] {logging_mixin.py:190} INFO - [2025-02-08T18:00:42.129+0000] {dagbag.py:387} ERROR - Failed to import: /opt/airflow/dags/pools.py
Traceback (most recent call last):
  File "/home/airflow/.local/lib/python3.12/site-packages/airflow/models/dagbag.py", line 383, in parse
    loader.exec_module(new_module)
  File "<frozen importlib._bootstrap_external>", line 999, in exec_module
  File "<frozen importlib._bootstrap>", line 488, in _call_with_frames_removed
  File "/opt/airflow/dags/pools.py", line 58, in <module>
    select_values = PostgresOperator(
                    ^^^^^^^^^^^^^^^^^
  File "/home/airflow/.local/lib/python3.12/site-packages/airflow/models/baseoperator.py", line 506, in apply_defaults
    result = func(self, **kwargs, default_args=default_args)
             ^^^^^^^^^^^^^^^^^^^^^^^^^^^^^^^^^^^^^^^^^^^^^^^
  File "/home/airflow/.local/lib/python3.12/site-packages/airflow/providers/postgres/operators/postgres.py", line 87, in __init__
    super().__init__(conn_id=postgres_conn_id, **kwargs)
  File "/home/airflow/.local/lib/python3.12/site-packages/airflow/models/baseoperator.py", line 506, in apply_defaults
    result = func(self, **kwargs, default_args=default_args)
             ^^^^^^^^^^^^^^^^^^^^^^^^^^^^^^^^^^^^^^^^^^^^^^^
  File "/home/airflow/.local/lib/python3.12/site-packages/airflow/providers/common/sql/operators/sql.py", line 244, in __init__
    super().__init__(conn_id=conn_id, database=database, **kwargs)
  File "/home/airflow/.local/lib/python3.12/site-packages/airflow/models/baseoperator.py", line 506, in apply_defaults
    result = func(self, **kwargs, default_args=default_args)
             ^^^^^^^^^^^^^^^^^^^^^^^^^^^^^^^^^^^^^^^^^^^^^^^
  File "/home/airflow/.local/lib/python3.12/site-packages/airflow/providers/common/sql/operators/sql.py", line 142, in __init__
    super().__init__(**kwargs)
  File "/home/airflow/.local/lib/python3.12/site-packages/airflow/models/baseoperator.py", line 506, in apply_defaults
    result = func(self, **kwargs, default_args=default_args)
             ^^^^^^^^^^^^^^^^^^^^^^^^^^^^^^^^^^^^^^^^^^^^^^^
  File "/home/airflow/.local/lib/python3.12/site-packages/airflow/models/baseoperator.py", line 975, in __init__
    task_group.add(self)
  File "/home/airflow/.local/lib/python3.12/site-packages/airflow/utils/task_group.py", line 256, in add
    raise DuplicateTaskIdFound(f"{node_type} id '{key}' has already been added to the DAG")
airflow.exceptions.DuplicateTaskIdFound: Task id 'select_values' has already been added to the DAG
[2025-02-08T18:00:42.157+0000] {processor.py:927} WARNING - No viable dags retrieved from /opt/airflow/dags/pools.py
[2025-02-08T18:00:42.267+0000] {processor.py:208} INFO - Processing /opt/airflow/dags/pools.py took 0.323 seconds
[2025-02-08T18:01:12.969+0000] {processor.py:186} INFO - Started process (PID=12371) to work on /opt/airflow/dags/pools.py
[2025-02-08T18:01:12.971+0000] {processor.py:914} INFO - Processing file /opt/airflow/dags/pools.py for tasks to queue
[2025-02-08T18:01:12.974+0000] {logging_mixin.py:190} INFO - [2025-02-08T18:01:12.973+0000] {dagbag.py:588} INFO - Filling up the DagBag from /opt/airflow/dags/pools.py
[2025-02-08T18:01:13.042+0000] {logging_mixin.py:190} INFO - [2025-02-08T18:01:13.019+0000] {dagbag.py:387} ERROR - Failed to import: /opt/airflow/dags/pools.py
Traceback (most recent call last):
  File "/home/airflow/.local/lib/python3.12/site-packages/airflow/models/dagbag.py", line 383, in parse
    loader.exec_module(new_module)
  File "<frozen importlib._bootstrap_external>", line 999, in exec_module
  File "<frozen importlib._bootstrap>", line 488, in _call_with_frames_removed
  File "/opt/airflow/dags/pools.py", line 58, in <module>
    select_values = PostgresOperator(
                    ^^^^^^^^^^^^^^^^^
  File "/home/airflow/.local/lib/python3.12/site-packages/airflow/models/baseoperator.py", line 506, in apply_defaults
    result = func(self, **kwargs, default_args=default_args)
             ^^^^^^^^^^^^^^^^^^^^^^^^^^^^^^^^^^^^^^^^^^^^^^^
  File "/home/airflow/.local/lib/python3.12/site-packages/airflow/providers/postgres/operators/postgres.py", line 87, in __init__
    super().__init__(conn_id=postgres_conn_id, **kwargs)
  File "/home/airflow/.local/lib/python3.12/site-packages/airflow/models/baseoperator.py", line 506, in apply_defaults
    result = func(self, **kwargs, default_args=default_args)
             ^^^^^^^^^^^^^^^^^^^^^^^^^^^^^^^^^^^^^^^^^^^^^^^
  File "/home/airflow/.local/lib/python3.12/site-packages/airflow/providers/common/sql/operators/sql.py", line 244, in __init__
    super().__init__(conn_id=conn_id, database=database, **kwargs)
  File "/home/airflow/.local/lib/python3.12/site-packages/airflow/models/baseoperator.py", line 506, in apply_defaults
    result = func(self, **kwargs, default_args=default_args)
             ^^^^^^^^^^^^^^^^^^^^^^^^^^^^^^^^^^^^^^^^^^^^^^^
  File "/home/airflow/.local/lib/python3.12/site-packages/airflow/providers/common/sql/operators/sql.py", line 142, in __init__
    super().__init__(**kwargs)
  File "/home/airflow/.local/lib/python3.12/site-packages/airflow/models/baseoperator.py", line 506, in apply_defaults
    result = func(self, **kwargs, default_args=default_args)
             ^^^^^^^^^^^^^^^^^^^^^^^^^^^^^^^^^^^^^^^^^^^^^^^
  File "/home/airflow/.local/lib/python3.12/site-packages/airflow/models/baseoperator.py", line 975, in __init__
    task_group.add(self)
  File "/home/airflow/.local/lib/python3.12/site-packages/airflow/utils/task_group.py", line 256, in add
    raise DuplicateTaskIdFound(f"{node_type} id '{key}' has already been added to the DAG")
airflow.exceptions.DuplicateTaskIdFound: Task id 'select_values' has already been added to the DAG
[2025-02-08T18:01:13.046+0000] {processor.py:927} WARNING - No viable dags retrieved from /opt/airflow/dags/pools.py
[2025-02-08T18:01:13.112+0000] {processor.py:208} INFO - Processing /opt/airflow/dags/pools.py took 0.161 seconds
[2025-02-08T18:01:43.658+0000] {processor.py:186} INFO - Started process (PID=12438) to work on /opt/airflow/dags/pools.py
[2025-02-08T18:01:43.660+0000] {processor.py:914} INFO - Processing file /opt/airflow/dags/pools.py for tasks to queue
[2025-02-08T18:01:43.662+0000] {logging_mixin.py:190} INFO - [2025-02-08T18:01:43.662+0000] {dagbag.py:588} INFO - Filling up the DagBag from /opt/airflow/dags/pools.py
[2025-02-08T18:01:43.706+0000] {logging_mixin.py:190} INFO - [2025-02-08T18:01:43.695+0000] {dagbag.py:387} ERROR - Failed to import: /opt/airflow/dags/pools.py
Traceback (most recent call last):
  File "/home/airflow/.local/lib/python3.12/site-packages/airflow/models/dagbag.py", line 383, in parse
    loader.exec_module(new_module)
  File "<frozen importlib._bootstrap_external>", line 999, in exec_module
  File "<frozen importlib._bootstrap>", line 488, in _call_with_frames_removed
  File "/opt/airflow/dags/pools.py", line 58, in <module>
    select_values = PostgresOperator(
                    ^^^^^^^^^^^^^^^^^
  File "/home/airflow/.local/lib/python3.12/site-packages/airflow/models/baseoperator.py", line 506, in apply_defaults
    result = func(self, **kwargs, default_args=default_args)
             ^^^^^^^^^^^^^^^^^^^^^^^^^^^^^^^^^^^^^^^^^^^^^^^
  File "/home/airflow/.local/lib/python3.12/site-packages/airflow/providers/postgres/operators/postgres.py", line 87, in __init__
    super().__init__(conn_id=postgres_conn_id, **kwargs)
  File "/home/airflow/.local/lib/python3.12/site-packages/airflow/models/baseoperator.py", line 506, in apply_defaults
    result = func(self, **kwargs, default_args=default_args)
             ^^^^^^^^^^^^^^^^^^^^^^^^^^^^^^^^^^^^^^^^^^^^^^^
  File "/home/airflow/.local/lib/python3.12/site-packages/airflow/providers/common/sql/operators/sql.py", line 244, in __init__
    super().__init__(conn_id=conn_id, database=database, **kwargs)
  File "/home/airflow/.local/lib/python3.12/site-packages/airflow/models/baseoperator.py", line 506, in apply_defaults
    result = func(self, **kwargs, default_args=default_args)
             ^^^^^^^^^^^^^^^^^^^^^^^^^^^^^^^^^^^^^^^^^^^^^^^
  File "/home/airflow/.local/lib/python3.12/site-packages/airflow/providers/common/sql/operators/sql.py", line 142, in __init__
    super().__init__(**kwargs)
  File "/home/airflow/.local/lib/python3.12/site-packages/airflow/models/baseoperator.py", line 506, in apply_defaults
    result = func(self, **kwargs, default_args=default_args)
             ^^^^^^^^^^^^^^^^^^^^^^^^^^^^^^^^^^^^^^^^^^^^^^^
  File "/home/airflow/.local/lib/python3.12/site-packages/airflow/models/baseoperator.py", line 975, in __init__
    task_group.add(self)
  File "/home/airflow/.local/lib/python3.12/site-packages/airflow/utils/task_group.py", line 256, in add
    raise DuplicateTaskIdFound(f"{node_type} id '{key}' has already been added to the DAG")
airflow.exceptions.DuplicateTaskIdFound: Task id 'select_values' has already been added to the DAG
[2025-02-08T18:01:43.708+0000] {processor.py:927} WARNING - No viable dags retrieved from /opt/airflow/dags/pools.py
[2025-02-08T18:01:43.749+0000] {processor.py:208} INFO - Processing /opt/airflow/dags/pools.py took 0.109 seconds
[2025-02-08T18:02:15.071+0000] {processor.py:186} INFO - Started process (PID=12479) to work on /opt/airflow/dags/pools.py
[2025-02-08T18:02:15.149+0000] {processor.py:914} INFO - Processing file /opt/airflow/dags/pools.py for tasks to queue
[2025-02-08T18:02:15.170+0000] {logging_mixin.py:190} INFO - [2025-02-08T18:02:15.169+0000] {dagbag.py:588} INFO - Filling up the DagBag from /opt/airflow/dags/pools.py
[2025-02-08T18:02:13.747+0000] {logging_mixin.py:190} INFO - [2025-02-08T18:02:13.386+0000] {dagbag.py:387} ERROR - Failed to import: /opt/airflow/dags/pools.py
Traceback (most recent call last):
  File "/home/airflow/.local/lib/python3.12/site-packages/airflow/models/dagbag.py", line 383, in parse
    loader.exec_module(new_module)
  File "<frozen importlib._bootstrap_external>", line 999, in exec_module
  File "<frozen importlib._bootstrap>", line 488, in _call_with_frames_removed
  File "/opt/airflow/dags/pools.py", line 58, in <module>
    select_values = PostgresOperator(
                    ^^^^^^^^^^^^^^^^^
  File "/home/airflow/.local/lib/python3.12/site-packages/airflow/models/baseoperator.py", line 506, in apply_defaults
    result = func(self, **kwargs, default_args=default_args)
             ^^^^^^^^^^^^^^^^^^^^^^^^^^^^^^^^^^^^^^^^^^^^^^^
  File "/home/airflow/.local/lib/python3.12/site-packages/airflow/providers/postgres/operators/postgres.py", line 87, in __init__
    super().__init__(conn_id=postgres_conn_id, **kwargs)
  File "/home/airflow/.local/lib/python3.12/site-packages/airflow/models/baseoperator.py", line 506, in apply_defaults
    result = func(self, **kwargs, default_args=default_args)
             ^^^^^^^^^^^^^^^^^^^^^^^^^^^^^^^^^^^^^^^^^^^^^^^
  File "/home/airflow/.local/lib/python3.12/site-packages/airflow/providers/common/sql/operators/sql.py", line 244, in __init__
    super().__init__(conn_id=conn_id, database=database, **kwargs)
  File "/home/airflow/.local/lib/python3.12/site-packages/airflow/models/baseoperator.py", line 506, in apply_defaults
    result = func(self, **kwargs, default_args=default_args)
             ^^^^^^^^^^^^^^^^^^^^^^^^^^^^^^^^^^^^^^^^^^^^^^^
  File "/home/airflow/.local/lib/python3.12/site-packages/airflow/providers/common/sql/operators/sql.py", line 142, in __init__
    super().__init__(**kwargs)
  File "/home/airflow/.local/lib/python3.12/site-packages/airflow/models/baseoperator.py", line 506, in apply_defaults
    result = func(self, **kwargs, default_args=default_args)
             ^^^^^^^^^^^^^^^^^^^^^^^^^^^^^^^^^^^^^^^^^^^^^^^
  File "/home/airflow/.local/lib/python3.12/site-packages/airflow/models/baseoperator.py", line 975, in __init__
    task_group.add(self)
  File "/home/airflow/.local/lib/python3.12/site-packages/airflow/utils/task_group.py", line 256, in add
    raise DuplicateTaskIdFound(f"{node_type} id '{key}' has already been added to the DAG")
airflow.exceptions.DuplicateTaskIdFound: Task id 'select_values' has already been added to the DAG
[2025-02-08T18:02:13.778+0000] {processor.py:927} WARNING - No viable dags retrieved from /opt/airflow/dags/pools.py
[2025-02-08T18:02:13.959+0000] {processor.py:208} INFO - Processing /opt/airflow/dags/pools.py took 1.672 seconds
[2025-02-08T18:02:46.913+0000] {processor.py:186} INFO - Started process (PID=12541) to work on /opt/airflow/dags/pools.py
[2025-02-08T18:02:46.918+0000] {processor.py:914} INFO - Processing file /opt/airflow/dags/pools.py for tasks to queue
[2025-02-08T18:02:46.922+0000] {logging_mixin.py:190} INFO - [2025-02-08T18:02:46.921+0000] {dagbag.py:588} INFO - Filling up the DagBag from /opt/airflow/dags/pools.py
[2025-02-08T18:02:46.974+0000] {logging_mixin.py:190} INFO - [2025-02-08T18:02:46.957+0000] {dagbag.py:387} ERROR - Failed to import: /opt/airflow/dags/pools.py
Traceback (most recent call last):
  File "/home/airflow/.local/lib/python3.12/site-packages/airflow/models/dagbag.py", line 383, in parse
    loader.exec_module(new_module)
  File "<frozen importlib._bootstrap_external>", line 999, in exec_module
  File "<frozen importlib._bootstrap>", line 488, in _call_with_frames_removed
  File "/opt/airflow/dags/pools.py", line 58, in <module>
    select_values = PostgresOperator(
                    ^^^^^^^^^^^^^^^^^
  File "/home/airflow/.local/lib/python3.12/site-packages/airflow/models/baseoperator.py", line 506, in apply_defaults
    result = func(self, **kwargs, default_args=default_args)
             ^^^^^^^^^^^^^^^^^^^^^^^^^^^^^^^^^^^^^^^^^^^^^^^
  File "/home/airflow/.local/lib/python3.12/site-packages/airflow/providers/postgres/operators/postgres.py", line 87, in __init__
    super().__init__(conn_id=postgres_conn_id, **kwargs)
  File "/home/airflow/.local/lib/python3.12/site-packages/airflow/models/baseoperator.py", line 506, in apply_defaults
    result = func(self, **kwargs, default_args=default_args)
             ^^^^^^^^^^^^^^^^^^^^^^^^^^^^^^^^^^^^^^^^^^^^^^^
  File "/home/airflow/.local/lib/python3.12/site-packages/airflow/providers/common/sql/operators/sql.py", line 244, in __init__
    super().__init__(conn_id=conn_id, database=database, **kwargs)
  File "/home/airflow/.local/lib/python3.12/site-packages/airflow/models/baseoperator.py", line 506, in apply_defaults
    result = func(self, **kwargs, default_args=default_args)
             ^^^^^^^^^^^^^^^^^^^^^^^^^^^^^^^^^^^^^^^^^^^^^^^
  File "/home/airflow/.local/lib/python3.12/site-packages/airflow/providers/common/sql/operators/sql.py", line 142, in __init__
    super().__init__(**kwargs)
  File "/home/airflow/.local/lib/python3.12/site-packages/airflow/models/baseoperator.py", line 506, in apply_defaults
    result = func(self, **kwargs, default_args=default_args)
             ^^^^^^^^^^^^^^^^^^^^^^^^^^^^^^^^^^^^^^^^^^^^^^^
  File "/home/airflow/.local/lib/python3.12/site-packages/airflow/models/baseoperator.py", line 975, in __init__
    task_group.add(self)
  File "/home/airflow/.local/lib/python3.12/site-packages/airflow/utils/task_group.py", line 256, in add
    raise DuplicateTaskIdFound(f"{node_type} id '{key}' has already been added to the DAG")
airflow.exceptions.DuplicateTaskIdFound: Task id 'select_values' has already been added to the DAG
[2025-02-08T18:02:46.979+0000] {processor.py:927} WARNING - No viable dags retrieved from /opt/airflow/dags/pools.py
[2025-02-08T18:02:47.040+0000] {processor.py:208} INFO - Processing /opt/airflow/dags/pools.py took 0.154 seconds
[2025-02-08T18:03:18.593+0000] {processor.py:186} INFO - Started process (PID=12613) to work on /opt/airflow/dags/pools.py
[2025-02-08T18:03:18.611+0000] {processor.py:914} INFO - Processing file /opt/airflow/dags/pools.py for tasks to queue
[2025-02-08T18:03:18.615+0000] {logging_mixin.py:190} INFO - [2025-02-08T18:03:18.614+0000] {dagbag.py:588} INFO - Filling up the DagBag from /opt/airflow/dags/pools.py
[2025-02-08T18:03:18.727+0000] {logging_mixin.py:190} INFO - [2025-02-08T18:03:18.705+0000] {dagbag.py:387} ERROR - Failed to import: /opt/airflow/dags/pools.py
Traceback (most recent call last):
  File "/home/airflow/.local/lib/python3.12/site-packages/airflow/models/dagbag.py", line 383, in parse
    loader.exec_module(new_module)
  File "<frozen importlib._bootstrap_external>", line 999, in exec_module
  File "<frozen importlib._bootstrap>", line 488, in _call_with_frames_removed
  File "/opt/airflow/dags/pools.py", line 58, in <module>
    select_values = PostgresOperator(
                    ^^^^^^^^^^^^^^^^^
  File "/home/airflow/.local/lib/python3.12/site-packages/airflow/models/baseoperator.py", line 506, in apply_defaults
    result = func(self, **kwargs, default_args=default_args)
             ^^^^^^^^^^^^^^^^^^^^^^^^^^^^^^^^^^^^^^^^^^^^^^^
  File "/home/airflow/.local/lib/python3.12/site-packages/airflow/providers/postgres/operators/postgres.py", line 87, in __init__
    super().__init__(conn_id=postgres_conn_id, **kwargs)
  File "/home/airflow/.local/lib/python3.12/site-packages/airflow/models/baseoperator.py", line 506, in apply_defaults
    result = func(self, **kwargs, default_args=default_args)
             ^^^^^^^^^^^^^^^^^^^^^^^^^^^^^^^^^^^^^^^^^^^^^^^
  File "/home/airflow/.local/lib/python3.12/site-packages/airflow/providers/common/sql/operators/sql.py", line 244, in __init__
    super().__init__(conn_id=conn_id, database=database, **kwargs)
  File "/home/airflow/.local/lib/python3.12/site-packages/airflow/models/baseoperator.py", line 506, in apply_defaults
    result = func(self, **kwargs, default_args=default_args)
             ^^^^^^^^^^^^^^^^^^^^^^^^^^^^^^^^^^^^^^^^^^^^^^^
  File "/home/airflow/.local/lib/python3.12/site-packages/airflow/providers/common/sql/operators/sql.py", line 142, in __init__
    super().__init__(**kwargs)
  File "/home/airflow/.local/lib/python3.12/site-packages/airflow/models/baseoperator.py", line 506, in apply_defaults
    result = func(self, **kwargs, default_args=default_args)
             ^^^^^^^^^^^^^^^^^^^^^^^^^^^^^^^^^^^^^^^^^^^^^^^
  File "/home/airflow/.local/lib/python3.12/site-packages/airflow/models/baseoperator.py", line 975, in __init__
    task_group.add(self)
  File "/home/airflow/.local/lib/python3.12/site-packages/airflow/utils/task_group.py", line 256, in add
    raise DuplicateTaskIdFound(f"{node_type} id '{key}' has already been added to the DAG")
airflow.exceptions.DuplicateTaskIdFound: Task id 'select_values' has already been added to the DAG
[2025-02-08T18:03:18.743+0000] {processor.py:927} WARNING - No viable dags retrieved from /opt/airflow/dags/pools.py
[2025-02-08T18:03:18.862+0000] {processor.py:208} INFO - Processing /opt/airflow/dags/pools.py took 0.298 seconds
[2025-02-08T18:03:49.104+0000] {processor.py:186} INFO - Started process (PID=12679) to work on /opt/airflow/dags/pools.py
[2025-02-08T18:03:49.107+0000] {processor.py:914} INFO - Processing file /opt/airflow/dags/pools.py for tasks to queue
[2025-02-08T18:03:49.111+0000] {logging_mixin.py:190} INFO - [2025-02-08T18:03:49.110+0000] {dagbag.py:588} INFO - Filling up the DagBag from /opt/airflow/dags/pools.py
[2025-02-08T18:03:49.182+0000] {logging_mixin.py:190} INFO - [2025-02-08T18:03:49.167+0000] {dagbag.py:387} ERROR - Failed to import: /opt/airflow/dags/pools.py
Traceback (most recent call last):
  File "/home/airflow/.local/lib/python3.12/site-packages/airflow/models/dagbag.py", line 383, in parse
    loader.exec_module(new_module)
  File "<frozen importlib._bootstrap_external>", line 999, in exec_module
  File "<frozen importlib._bootstrap>", line 488, in _call_with_frames_removed
  File "/opt/airflow/dags/pools.py", line 58, in <module>
    select_values = PostgresOperator(
                    ^^^^^^^^^^^^^^^^^
  File "/home/airflow/.local/lib/python3.12/site-packages/airflow/models/baseoperator.py", line 506, in apply_defaults
    result = func(self, **kwargs, default_args=default_args)
             ^^^^^^^^^^^^^^^^^^^^^^^^^^^^^^^^^^^^^^^^^^^^^^^
  File "/home/airflow/.local/lib/python3.12/site-packages/airflow/providers/postgres/operators/postgres.py", line 87, in __init__
    super().__init__(conn_id=postgres_conn_id, **kwargs)
  File "/home/airflow/.local/lib/python3.12/site-packages/airflow/models/baseoperator.py", line 506, in apply_defaults
    result = func(self, **kwargs, default_args=default_args)
             ^^^^^^^^^^^^^^^^^^^^^^^^^^^^^^^^^^^^^^^^^^^^^^^
  File "/home/airflow/.local/lib/python3.12/site-packages/airflow/providers/common/sql/operators/sql.py", line 244, in __init__
    super().__init__(conn_id=conn_id, database=database, **kwargs)
  File "/home/airflow/.local/lib/python3.12/site-packages/airflow/models/baseoperator.py", line 506, in apply_defaults
    result = func(self, **kwargs, default_args=default_args)
             ^^^^^^^^^^^^^^^^^^^^^^^^^^^^^^^^^^^^^^^^^^^^^^^
  File "/home/airflow/.local/lib/python3.12/site-packages/airflow/providers/common/sql/operators/sql.py", line 142, in __init__
    super().__init__(**kwargs)
  File "/home/airflow/.local/lib/python3.12/site-packages/airflow/models/baseoperator.py", line 506, in apply_defaults
    result = func(self, **kwargs, default_args=default_args)
             ^^^^^^^^^^^^^^^^^^^^^^^^^^^^^^^^^^^^^^^^^^^^^^^
  File "/home/airflow/.local/lib/python3.12/site-packages/airflow/models/baseoperator.py", line 975, in __init__
    task_group.add(self)
  File "/home/airflow/.local/lib/python3.12/site-packages/airflow/utils/task_group.py", line 256, in add
    raise DuplicateTaskIdFound(f"{node_type} id '{key}' has already been added to the DAG")
airflow.exceptions.DuplicateTaskIdFound: Task id 'select_values' has already been added to the DAG
[2025-02-08T18:03:49.186+0000] {processor.py:927} WARNING - No viable dags retrieved from /opt/airflow/dags/pools.py
[2025-02-08T18:03:49.229+0000] {processor.py:208} INFO - Processing /opt/airflow/dags/pools.py took 0.145 seconds
[2025-02-08T18:04:19.577+0000] {processor.py:186} INFO - Started process (PID=12746) to work on /opt/airflow/dags/pools.py
[2025-02-08T18:04:19.579+0000] {processor.py:914} INFO - Processing file /opt/airflow/dags/pools.py for tasks to queue
[2025-02-08T18:04:19.582+0000] {logging_mixin.py:190} INFO - [2025-02-08T18:04:19.582+0000] {dagbag.py:588} INFO - Filling up the DagBag from /opt/airflow/dags/pools.py
[2025-02-08T18:04:19.627+0000] {logging_mixin.py:190} INFO - [2025-02-08T18:04:19.616+0000] {dagbag.py:387} ERROR - Failed to import: /opt/airflow/dags/pools.py
Traceback (most recent call last):
  File "/home/airflow/.local/lib/python3.12/site-packages/airflow/models/dagbag.py", line 383, in parse
    loader.exec_module(new_module)
  File "<frozen importlib._bootstrap_external>", line 999, in exec_module
  File "<frozen importlib._bootstrap>", line 488, in _call_with_frames_removed
  File "/opt/airflow/dags/pools.py", line 58, in <module>
    select_values = PostgresOperator(
                    ^^^^^^^^^^^^^^^^^
  File "/home/airflow/.local/lib/python3.12/site-packages/airflow/models/baseoperator.py", line 506, in apply_defaults
    result = func(self, **kwargs, default_args=default_args)
             ^^^^^^^^^^^^^^^^^^^^^^^^^^^^^^^^^^^^^^^^^^^^^^^
  File "/home/airflow/.local/lib/python3.12/site-packages/airflow/providers/postgres/operators/postgres.py", line 87, in __init__
    super().__init__(conn_id=postgres_conn_id, **kwargs)
  File "/home/airflow/.local/lib/python3.12/site-packages/airflow/models/baseoperator.py", line 506, in apply_defaults
    result = func(self, **kwargs, default_args=default_args)
             ^^^^^^^^^^^^^^^^^^^^^^^^^^^^^^^^^^^^^^^^^^^^^^^
  File "/home/airflow/.local/lib/python3.12/site-packages/airflow/providers/common/sql/operators/sql.py", line 244, in __init__
    super().__init__(conn_id=conn_id, database=database, **kwargs)
  File "/home/airflow/.local/lib/python3.12/site-packages/airflow/models/baseoperator.py", line 506, in apply_defaults
    result = func(self, **kwargs, default_args=default_args)
             ^^^^^^^^^^^^^^^^^^^^^^^^^^^^^^^^^^^^^^^^^^^^^^^
  File "/home/airflow/.local/lib/python3.12/site-packages/airflow/providers/common/sql/operators/sql.py", line 142, in __init__
    super().__init__(**kwargs)
  File "/home/airflow/.local/lib/python3.12/site-packages/airflow/models/baseoperator.py", line 506, in apply_defaults
    result = func(self, **kwargs, default_args=default_args)
             ^^^^^^^^^^^^^^^^^^^^^^^^^^^^^^^^^^^^^^^^^^^^^^^
  File "/home/airflow/.local/lib/python3.12/site-packages/airflow/models/baseoperator.py", line 975, in __init__
    task_group.add(self)
  File "/home/airflow/.local/lib/python3.12/site-packages/airflow/utils/task_group.py", line 256, in add
    raise DuplicateTaskIdFound(f"{node_type} id '{key}' has already been added to the DAG")
airflow.exceptions.DuplicateTaskIdFound: Task id 'select_values' has already been added to the DAG
[2025-02-08T18:04:19.631+0000] {processor.py:927} WARNING - No viable dags retrieved from /opt/airflow/dags/pools.py
[2025-02-08T18:04:19.693+0000] {processor.py:208} INFO - Processing /opt/airflow/dags/pools.py took 0.135 seconds
[2025-02-08T18:04:49.842+0000] {processor.py:186} INFO - Started process (PID=12812) to work on /opt/airflow/dags/pools.py
[2025-02-08T18:04:49.844+0000] {processor.py:914} INFO - Processing file /opt/airflow/dags/pools.py for tasks to queue
[2025-02-08T18:04:49.846+0000] {logging_mixin.py:190} INFO - [2025-02-08T18:04:49.846+0000] {dagbag.py:588} INFO - Filling up the DagBag from /opt/airflow/dags/pools.py
[2025-02-08T18:04:49.886+0000] {logging_mixin.py:190} INFO - [2025-02-08T18:04:49.876+0000] {dagbag.py:387} ERROR - Failed to import: /opt/airflow/dags/pools.py
Traceback (most recent call last):
  File "/home/airflow/.local/lib/python3.12/site-packages/airflow/models/dagbag.py", line 383, in parse
    loader.exec_module(new_module)
  File "<frozen importlib._bootstrap_external>", line 999, in exec_module
  File "<frozen importlib._bootstrap>", line 488, in _call_with_frames_removed
  File "/opt/airflow/dags/pools.py", line 58, in <module>
    select_values = PostgresOperator(
                    ^^^^^^^^^^^^^^^^^
  File "/home/airflow/.local/lib/python3.12/site-packages/airflow/models/baseoperator.py", line 506, in apply_defaults
    result = func(self, **kwargs, default_args=default_args)
             ^^^^^^^^^^^^^^^^^^^^^^^^^^^^^^^^^^^^^^^^^^^^^^^
  File "/home/airflow/.local/lib/python3.12/site-packages/airflow/providers/postgres/operators/postgres.py", line 87, in __init__
    super().__init__(conn_id=postgres_conn_id, **kwargs)
  File "/home/airflow/.local/lib/python3.12/site-packages/airflow/models/baseoperator.py", line 506, in apply_defaults
    result = func(self, **kwargs, default_args=default_args)
             ^^^^^^^^^^^^^^^^^^^^^^^^^^^^^^^^^^^^^^^^^^^^^^^
  File "/home/airflow/.local/lib/python3.12/site-packages/airflow/providers/common/sql/operators/sql.py", line 244, in __init__
    super().__init__(conn_id=conn_id, database=database, **kwargs)
  File "/home/airflow/.local/lib/python3.12/site-packages/airflow/models/baseoperator.py", line 506, in apply_defaults
    result = func(self, **kwargs, default_args=default_args)
             ^^^^^^^^^^^^^^^^^^^^^^^^^^^^^^^^^^^^^^^^^^^^^^^
  File "/home/airflow/.local/lib/python3.12/site-packages/airflow/providers/common/sql/operators/sql.py", line 142, in __init__
    super().__init__(**kwargs)
  File "/home/airflow/.local/lib/python3.12/site-packages/airflow/models/baseoperator.py", line 506, in apply_defaults
    result = func(self, **kwargs, default_args=default_args)
             ^^^^^^^^^^^^^^^^^^^^^^^^^^^^^^^^^^^^^^^^^^^^^^^
  File "/home/airflow/.local/lib/python3.12/site-packages/airflow/models/baseoperator.py", line 975, in __init__
    task_group.add(self)
  File "/home/airflow/.local/lib/python3.12/site-packages/airflow/utils/task_group.py", line 256, in add
    raise DuplicateTaskIdFound(f"{node_type} id '{key}' has already been added to the DAG")
airflow.exceptions.DuplicateTaskIdFound: Task id 'select_values' has already been added to the DAG
[2025-02-08T18:04:49.889+0000] {processor.py:927} WARNING - No viable dags retrieved from /opt/airflow/dags/pools.py
[2025-02-08T18:04:49.927+0000] {processor.py:208} INFO - Processing /opt/airflow/dags/pools.py took 0.102 seconds
[2025-02-08T18:05:20.129+0000] {processor.py:186} INFO - Started process (PID=12879) to work on /opt/airflow/dags/pools.py
[2025-02-08T18:05:20.131+0000] {processor.py:914} INFO - Processing file /opt/airflow/dags/pools.py for tasks to queue
[2025-02-08T18:05:20.136+0000] {logging_mixin.py:190} INFO - [2025-02-08T18:05:20.135+0000] {dagbag.py:588} INFO - Filling up the DagBag from /opt/airflow/dags/pools.py
[2025-02-08T18:05:20.259+0000] {logging_mixin.py:190} INFO - [2025-02-08T18:05:20.240+0000] {dagbag.py:387} ERROR - Failed to import: /opt/airflow/dags/pools.py
Traceback (most recent call last):
  File "/home/airflow/.local/lib/python3.12/site-packages/airflow/models/dagbag.py", line 383, in parse
    loader.exec_module(new_module)
  File "<frozen importlib._bootstrap_external>", line 999, in exec_module
  File "<frozen importlib._bootstrap>", line 488, in _call_with_frames_removed
  File "/opt/airflow/dags/pools.py", line 58, in <module>
    select_values = PostgresOperator(
                    ^^^^^^^^^^^^^^^^^
  File "/home/airflow/.local/lib/python3.12/site-packages/airflow/models/baseoperator.py", line 506, in apply_defaults
    result = func(self, **kwargs, default_args=default_args)
             ^^^^^^^^^^^^^^^^^^^^^^^^^^^^^^^^^^^^^^^^^^^^^^^
  File "/home/airflow/.local/lib/python3.12/site-packages/airflow/providers/postgres/operators/postgres.py", line 87, in __init__
    super().__init__(conn_id=postgres_conn_id, **kwargs)
  File "/home/airflow/.local/lib/python3.12/site-packages/airflow/models/baseoperator.py", line 506, in apply_defaults
    result = func(self, **kwargs, default_args=default_args)
             ^^^^^^^^^^^^^^^^^^^^^^^^^^^^^^^^^^^^^^^^^^^^^^^
  File "/home/airflow/.local/lib/python3.12/site-packages/airflow/providers/common/sql/operators/sql.py", line 244, in __init__
    super().__init__(conn_id=conn_id, database=database, **kwargs)
  File "/home/airflow/.local/lib/python3.12/site-packages/airflow/models/baseoperator.py", line 506, in apply_defaults
    result = func(self, **kwargs, default_args=default_args)
             ^^^^^^^^^^^^^^^^^^^^^^^^^^^^^^^^^^^^^^^^^^^^^^^
  File "/home/airflow/.local/lib/python3.12/site-packages/airflow/providers/common/sql/operators/sql.py", line 142, in __init__
    super().__init__(**kwargs)
  File "/home/airflow/.local/lib/python3.12/site-packages/airflow/models/baseoperator.py", line 506, in apply_defaults
    result = func(self, **kwargs, default_args=default_args)
             ^^^^^^^^^^^^^^^^^^^^^^^^^^^^^^^^^^^^^^^^^^^^^^^
  File "/home/airflow/.local/lib/python3.12/site-packages/airflow/models/baseoperator.py", line 975, in __init__
    task_group.add(self)
  File "/home/airflow/.local/lib/python3.12/site-packages/airflow/utils/task_group.py", line 256, in add
    raise DuplicateTaskIdFound(f"{node_type} id '{key}' has already been added to the DAG")
airflow.exceptions.DuplicateTaskIdFound: Task id 'select_values' has already been added to the DAG
[2025-02-08T18:05:20.262+0000] {processor.py:927} WARNING - No viable dags retrieved from /opt/airflow/dags/pools.py
[2025-02-08T18:05:20.319+0000] {processor.py:208} INFO - Processing /opt/airflow/dags/pools.py took 0.221 seconds
[2025-02-08T18:05:50.392+0000] {processor.py:186} INFO - Started process (PID=12932) to work on /opt/airflow/dags/pools.py
[2025-02-08T18:05:50.393+0000] {processor.py:914} INFO - Processing file /opt/airflow/dags/pools.py for tasks to queue
[2025-02-08T18:05:50.396+0000] {logging_mixin.py:190} INFO - [2025-02-08T18:05:50.395+0000] {dagbag.py:588} INFO - Filling up the DagBag from /opt/airflow/dags/pools.py
[2025-02-08T18:05:50.435+0000] {logging_mixin.py:190} INFO - [2025-02-08T18:05:50.424+0000] {dagbag.py:387} ERROR - Failed to import: /opt/airflow/dags/pools.py
Traceback (most recent call last):
  File "/home/airflow/.local/lib/python3.12/site-packages/airflow/models/dagbag.py", line 383, in parse
    loader.exec_module(new_module)
  File "<frozen importlib._bootstrap_external>", line 999, in exec_module
  File "<frozen importlib._bootstrap>", line 488, in _call_with_frames_removed
  File "/opt/airflow/dags/pools.py", line 58, in <module>
    select_values = PostgresOperator(
                    ^^^^^^^^^^^^^^^^^
  File "/home/airflow/.local/lib/python3.12/site-packages/airflow/models/baseoperator.py", line 506, in apply_defaults
    result = func(self, **kwargs, default_args=default_args)
             ^^^^^^^^^^^^^^^^^^^^^^^^^^^^^^^^^^^^^^^^^^^^^^^
  File "/home/airflow/.local/lib/python3.12/site-packages/airflow/providers/postgres/operators/postgres.py", line 87, in __init__
    super().__init__(conn_id=postgres_conn_id, **kwargs)
  File "/home/airflow/.local/lib/python3.12/site-packages/airflow/models/baseoperator.py", line 506, in apply_defaults
    result = func(self, **kwargs, default_args=default_args)
             ^^^^^^^^^^^^^^^^^^^^^^^^^^^^^^^^^^^^^^^^^^^^^^^
  File "/home/airflow/.local/lib/python3.12/site-packages/airflow/providers/common/sql/operators/sql.py", line 244, in __init__
    super().__init__(conn_id=conn_id, database=database, **kwargs)
  File "/home/airflow/.local/lib/python3.12/site-packages/airflow/models/baseoperator.py", line 506, in apply_defaults
    result = func(self, **kwargs, default_args=default_args)
             ^^^^^^^^^^^^^^^^^^^^^^^^^^^^^^^^^^^^^^^^^^^^^^^
  File "/home/airflow/.local/lib/python3.12/site-packages/airflow/providers/common/sql/operators/sql.py", line 142, in __init__
    super().__init__(**kwargs)
  File "/home/airflow/.local/lib/python3.12/site-packages/airflow/models/baseoperator.py", line 506, in apply_defaults
    result = func(self, **kwargs, default_args=default_args)
             ^^^^^^^^^^^^^^^^^^^^^^^^^^^^^^^^^^^^^^^^^^^^^^^
  File "/home/airflow/.local/lib/python3.12/site-packages/airflow/models/baseoperator.py", line 975, in __init__
    task_group.add(self)
  File "/home/airflow/.local/lib/python3.12/site-packages/airflow/utils/task_group.py", line 256, in add
    raise DuplicateTaskIdFound(f"{node_type} id '{key}' has already been added to the DAG")
airflow.exceptions.DuplicateTaskIdFound: Task id 'select_values' has already been added to the DAG
[2025-02-08T18:05:50.437+0000] {processor.py:927} WARNING - No viable dags retrieved from /opt/airflow/dags/pools.py
[2025-02-08T18:05:50.496+0000] {processor.py:208} INFO - Processing /opt/airflow/dags/pools.py took 0.119 seconds
[2025-02-08T18:06:26.248+0000] {processor.py:186} INFO - Started process (PID=12989) to work on /opt/airflow/dags/pools.py
[2025-02-08T18:06:26.252+0000] {processor.py:914} INFO - Processing file /opt/airflow/dags/pools.py for tasks to queue
[2025-02-08T18:06:26.256+0000] {logging_mixin.py:190} INFO - [2025-02-08T18:06:26.255+0000] {dagbag.py:588} INFO - Filling up the DagBag from /opt/airflow/dags/pools.py
[2025-02-08T18:06:26.610+0000] {logging_mixin.py:190} INFO - [2025-02-08T18:06:26.457+0000] {dagbag.py:387} ERROR - Failed to import: /opt/airflow/dags/pools.py
Traceback (most recent call last):
  File "/home/airflow/.local/lib/python3.12/site-packages/airflow/models/dagbag.py", line 383, in parse
    loader.exec_module(new_module)
  File "<frozen importlib._bootstrap_external>", line 999, in exec_module
  File "<frozen importlib._bootstrap>", line 488, in _call_with_frames_removed
  File "/opt/airflow/dags/pools.py", line 58, in <module>
    select_values = PostgresOperator(
                    ^^^^^^^^^^^^^^^^^
  File "/home/airflow/.local/lib/python3.12/site-packages/airflow/models/baseoperator.py", line 506, in apply_defaults
    result = func(self, **kwargs, default_args=default_args)
             ^^^^^^^^^^^^^^^^^^^^^^^^^^^^^^^^^^^^^^^^^^^^^^^
  File "/home/airflow/.local/lib/python3.12/site-packages/airflow/providers/postgres/operators/postgres.py", line 87, in __init__
    super().__init__(conn_id=postgres_conn_id, **kwargs)
  File "/home/airflow/.local/lib/python3.12/site-packages/airflow/models/baseoperator.py", line 506, in apply_defaults
    result = func(self, **kwargs, default_args=default_args)
             ^^^^^^^^^^^^^^^^^^^^^^^^^^^^^^^^^^^^^^^^^^^^^^^
  File "/home/airflow/.local/lib/python3.12/site-packages/airflow/providers/common/sql/operators/sql.py", line 244, in __init__
    super().__init__(conn_id=conn_id, database=database, **kwargs)
  File "/home/airflow/.local/lib/python3.12/site-packages/airflow/models/baseoperator.py", line 506, in apply_defaults
    result = func(self, **kwargs, default_args=default_args)
             ^^^^^^^^^^^^^^^^^^^^^^^^^^^^^^^^^^^^^^^^^^^^^^^
  File "/home/airflow/.local/lib/python3.12/site-packages/airflow/providers/common/sql/operators/sql.py", line 142, in __init__
    super().__init__(**kwargs)
  File "/home/airflow/.local/lib/python3.12/site-packages/airflow/models/baseoperator.py", line 506, in apply_defaults
    result = func(self, **kwargs, default_args=default_args)
             ^^^^^^^^^^^^^^^^^^^^^^^^^^^^^^^^^^^^^^^^^^^^^^^
  File "/home/airflow/.local/lib/python3.12/site-packages/airflow/models/baseoperator.py", line 975, in __init__
    task_group.add(self)
  File "/home/airflow/.local/lib/python3.12/site-packages/airflow/utils/task_group.py", line 256, in add
    raise DuplicateTaskIdFound(f"{node_type} id '{key}' has already been added to the DAG")
airflow.exceptions.DuplicateTaskIdFound: Task id 'select_values' has already been added to the DAG
[2025-02-08T18:06:26.700+0000] {processor.py:927} WARNING - No viable dags retrieved from /opt/airflow/dags/pools.py
[2025-02-08T18:06:26.963+0000] {processor.py:208} INFO - Processing /opt/airflow/dags/pools.py took 0.752 seconds
[2025-02-08T18:06:59.081+0000] {processor.py:186} INFO - Started process (PID=13053) to work on /opt/airflow/dags/pools.py
[2025-02-08T18:06:59.086+0000] {processor.py:914} INFO - Processing file /opt/airflow/dags/pools.py for tasks to queue
[2025-02-08T18:06:59.089+0000] {logging_mixin.py:190} INFO - [2025-02-08T18:06:59.088+0000] {dagbag.py:588} INFO - Filling up the DagBag from /opt/airflow/dags/pools.py
[2025-02-08T18:06:59.149+0000] {logging_mixin.py:190} INFO - [2025-02-08T18:06:59.137+0000] {dagbag.py:387} ERROR - Failed to import: /opt/airflow/dags/pools.py
Traceback (most recent call last):
  File "/home/airflow/.local/lib/python3.12/site-packages/airflow/models/dagbag.py", line 383, in parse
    loader.exec_module(new_module)
  File "<frozen importlib._bootstrap_external>", line 999, in exec_module
  File "<frozen importlib._bootstrap>", line 488, in _call_with_frames_removed
  File "/opt/airflow/dags/pools.py", line 58, in <module>
    select_values = PostgresOperator(
                    ^^^^^^^^^^^^^^^^^
  File "/home/airflow/.local/lib/python3.12/site-packages/airflow/models/baseoperator.py", line 506, in apply_defaults
    result = func(self, **kwargs, default_args=default_args)
             ^^^^^^^^^^^^^^^^^^^^^^^^^^^^^^^^^^^^^^^^^^^^^^^
  File "/home/airflow/.local/lib/python3.12/site-packages/airflow/providers/postgres/operators/postgres.py", line 87, in __init__
    super().__init__(conn_id=postgres_conn_id, **kwargs)
  File "/home/airflow/.local/lib/python3.12/site-packages/airflow/models/baseoperator.py", line 506, in apply_defaults
    result = func(self, **kwargs, default_args=default_args)
             ^^^^^^^^^^^^^^^^^^^^^^^^^^^^^^^^^^^^^^^^^^^^^^^
  File "/home/airflow/.local/lib/python3.12/site-packages/airflow/providers/common/sql/operators/sql.py", line 244, in __init__
    super().__init__(conn_id=conn_id, database=database, **kwargs)
  File "/home/airflow/.local/lib/python3.12/site-packages/airflow/models/baseoperator.py", line 506, in apply_defaults
    result = func(self, **kwargs, default_args=default_args)
             ^^^^^^^^^^^^^^^^^^^^^^^^^^^^^^^^^^^^^^^^^^^^^^^
  File "/home/airflow/.local/lib/python3.12/site-packages/airflow/providers/common/sql/operators/sql.py", line 142, in __init__
    super().__init__(**kwargs)
  File "/home/airflow/.local/lib/python3.12/site-packages/airflow/models/baseoperator.py", line 506, in apply_defaults
    result = func(self, **kwargs, default_args=default_args)
             ^^^^^^^^^^^^^^^^^^^^^^^^^^^^^^^^^^^^^^^^^^^^^^^
  File "/home/airflow/.local/lib/python3.12/site-packages/airflow/models/baseoperator.py", line 975, in __init__
    task_group.add(self)
  File "/home/airflow/.local/lib/python3.12/site-packages/airflow/utils/task_group.py", line 256, in add
    raise DuplicateTaskIdFound(f"{node_type} id '{key}' has already been added to the DAG")
airflow.exceptions.DuplicateTaskIdFound: Task id 'select_values' has already been added to the DAG
[2025-02-08T18:06:59.165+0000] {processor.py:927} WARNING - No viable dags retrieved from /opt/airflow/dags/pools.py
[2025-02-08T18:06:59.282+0000] {processor.py:208} INFO - Processing /opt/airflow/dags/pools.py took 0.224 seconds
[2025-02-08T18:07:38.598+0000] {processor.py:186} INFO - Started process (PID=13117) to work on /opt/airflow/dags/pools.py
[2025-02-08T18:07:38.632+0000] {processor.py:914} INFO - Processing file /opt/airflow/dags/pools.py for tasks to queue
[2025-02-08T18:07:38.651+0000] {logging_mixin.py:190} INFO - [2025-02-08T18:07:38.650+0000] {dagbag.py:588} INFO - Filling up the DagBag from /opt/airflow/dags/pools.py
[2025-02-08T18:07:39.943+0000] {logging_mixin.py:190} INFO - [2025-02-08T18:07:39.784+0000] {dagbag.py:387} ERROR - Failed to import: /opt/airflow/dags/pools.py
Traceback (most recent call last):
  File "/home/airflow/.local/lib/python3.12/site-packages/airflow/models/dagbag.py", line 383, in parse
    loader.exec_module(new_module)
  File "<frozen importlib._bootstrap_external>", line 999, in exec_module
  File "<frozen importlib._bootstrap>", line 488, in _call_with_frames_removed
  File "/opt/airflow/dags/pools.py", line 26, in <module>
    simulate_task_1 = PythonOperator(
                      ^^^^^^^^^^^^^^^
  File "/home/airflow/.local/lib/python3.12/site-packages/airflow/models/baseoperator.py", line 506, in apply_defaults
    result = func(self, **kwargs, default_args=default_args)
             ^^^^^^^^^^^^^^^^^^^^^^^^^^^^^^^^^^^^^^^^^^^^^^^
  File "/home/airflow/.local/lib/python3.12/site-packages/airflow/operators/python.py", line 222, in __init__
    super().__init__(**kwargs)
  File "/home/airflow/.local/lib/python3.12/site-packages/airflow/models/baseoperator.py", line 506, in apply_defaults
    result = func(self, **kwargs, default_args=default_args)
             ^^^^^^^^^^^^^^^^^^^^^^^^^^^^^^^^^^^^^^^^^^^^^^^
  File "/home/airflow/.local/lib/python3.12/site-packages/airflow/models/baseoperator.py", line 957, in __init__
    raise AirflowException(
airflow.exceptions.AirflowException: Invalid arguments were passed to PythonOperator (task_id: simulate_task_1). Invalid arguments were:
**kwargs: {'piority_weight': 2}
[2025-02-08T18:07:39.947+0000] {processor.py:927} WARNING - No viable dags retrieved from /opt/airflow/dags/pools.py
[2025-02-08T18:07:40.149+0000] {processor.py:208} INFO - Processing /opt/airflow/dags/pools.py took 1.635 seconds
[2025-02-08T18:07:59.472+0000] {processor.py:186} INFO - Started process (PID=13134) to work on /opt/airflow/dags/pools.py
[2025-02-08T18:07:59.476+0000] {processor.py:914} INFO - Processing file /opt/airflow/dags/pools.py for tasks to queue
[2025-02-08T18:07:59.497+0000] {logging_mixin.py:190} INFO - [2025-02-08T18:07:59.496+0000] {dagbag.py:588} INFO - Filling up the DagBag from /opt/airflow/dags/pools.py
[2025-02-08T18:07:59.581+0000] {logging_mixin.py:190} INFO - [2025-02-08T18:07:59.570+0000] {dagbag.py:387} ERROR - Failed to import: /opt/airflow/dags/pools.py
Traceback (most recent call last):
  File "/home/airflow/.local/lib/python3.12/site-packages/airflow/models/dagbag.py", line 383, in parse
    loader.exec_module(new_module)
  File "<frozen importlib._bootstrap_external>", line 999, in exec_module
  File "<frozen importlib._bootstrap>", line 488, in _call_with_frames_removed
  File "/opt/airflow/dags/pools.py", line 26, in <module>
    simulate_task_1 = PythonOperator(
                      ^^^^^^^^^^^^^^^
  File "/home/airflow/.local/lib/python3.12/site-packages/airflow/models/baseoperator.py", line 506, in apply_defaults
    result = func(self, **kwargs, default_args=default_args)
             ^^^^^^^^^^^^^^^^^^^^^^^^^^^^^^^^^^^^^^^^^^^^^^^
  File "/home/airflow/.local/lib/python3.12/site-packages/airflow/operators/python.py", line 222, in __init__
    super().__init__(**kwargs)
  File "/home/airflow/.local/lib/python3.12/site-packages/airflow/models/baseoperator.py", line 506, in apply_defaults
    result = func(self, **kwargs, default_args=default_args)
             ^^^^^^^^^^^^^^^^^^^^^^^^^^^^^^^^^^^^^^^^^^^^^^^
  File "/home/airflow/.local/lib/python3.12/site-packages/airflow/models/baseoperator.py", line 957, in __init__
    raise AirflowException(
airflow.exceptions.AirflowException: Invalid arguments were passed to PythonOperator (task_id: simulate_task_1). Invalid arguments were:
**kwargs: {'piority_weight': 2}
[2025-02-08T18:07:59.590+0000] {processor.py:927} WARNING - No viable dags retrieved from /opt/airflow/dags/pools.py
[2025-02-08T18:07:59.725+0000] {processor.py:208} INFO - Processing /opt/airflow/dags/pools.py took 0.292 seconds
[2025-02-08T18:08:31.201+0000] {processor.py:186} INFO - Started process (PID=13184) to work on /opt/airflow/dags/pools.py
[2025-02-08T18:08:31.215+0000] {processor.py:914} INFO - Processing file /opt/airflow/dags/pools.py for tasks to queue
[2025-02-08T18:08:31.234+0000] {logging_mixin.py:190} INFO - [2025-02-08T18:08:31.233+0000] {dagbag.py:588} INFO - Filling up the DagBag from /opt/airflow/dags/pools.py
[2025-02-08T18:08:31.479+0000] {logging_mixin.py:190} INFO - [2025-02-08T18:08:31.391+0000] {dagbag.py:387} ERROR - Failed to import: /opt/airflow/dags/pools.py
Traceback (most recent call last):
  File "/home/airflow/.local/lib/python3.12/site-packages/airflow/models/dagbag.py", line 383, in parse
    loader.exec_module(new_module)
  File "<frozen importlib._bootstrap_external>", line 999, in exec_module
  File "<frozen importlib._bootstrap>", line 488, in _call_with_frames_removed
  File "/opt/airflow/dags/pools.py", line 26, in <module>
    simulate_task_1 = PythonOperator(
                      ^^^^^^^^^^^^^^^
  File "/home/airflow/.local/lib/python3.12/site-packages/airflow/models/baseoperator.py", line 506, in apply_defaults
    result = func(self, **kwargs, default_args=default_args)
             ^^^^^^^^^^^^^^^^^^^^^^^^^^^^^^^^^^^^^^^^^^^^^^^
  File "/home/airflow/.local/lib/python3.12/site-packages/airflow/operators/python.py", line 222, in __init__
    super().__init__(**kwargs)
  File "/home/airflow/.local/lib/python3.12/site-packages/airflow/models/baseoperator.py", line 506, in apply_defaults
    result = func(self, **kwargs, default_args=default_args)
             ^^^^^^^^^^^^^^^^^^^^^^^^^^^^^^^^^^^^^^^^^^^^^^^
  File "/home/airflow/.local/lib/python3.12/site-packages/airflow/models/baseoperator.py", line 957, in __init__
    raise AirflowException(
airflow.exceptions.AirflowException: Invalid arguments were passed to PythonOperator (task_id: simulate_task_1). Invalid arguments were:
**kwargs: {'piority_weight': 2}
[2025-02-08T18:08:31.495+0000] {processor.py:927} WARNING - No viable dags retrieved from /opt/airflow/dags/pools.py
[2025-02-08T18:08:31.629+0000] {processor.py:208} INFO - Processing /opt/airflow/dags/pools.py took 0.474 seconds
[2025-02-08T18:08:54.381+0000] {processor.py:186} INFO - Started process (PID=13208) to work on /opt/airflow/dags/pools.py
[2025-02-08T18:08:54.399+0000] {processor.py:914} INFO - Processing file /opt/airflow/dags/pools.py for tasks to queue
[2025-02-08T18:08:54.414+0000] {logging_mixin.py:190} INFO - [2025-02-08T18:08:54.413+0000] {dagbag.py:588} INFO - Filling up the DagBag from /opt/airflow/dags/pools.py
[2025-02-08T18:08:55.352+0000] {logging_mixin.py:190} INFO - [2025-02-08T18:08:55.029+0000] {dagbag.py:387} ERROR - Failed to import: /opt/airflow/dags/pools.py
Traceback (most recent call last):
  File "/home/airflow/.local/lib/python3.12/site-packages/airflow/models/dagbag.py", line 383, in parse
    loader.exec_module(new_module)
  File "<frozen importlib._bootstrap_external>", line 999, in exec_module
  File "<frozen importlib._bootstrap>", line 488, in _call_with_frames_removed
  File "/opt/airflow/dags/pools.py", line 26, in <module>
    simulate_task_1 = PythonOperator(
                      ^^^^^^^^^^^^^^^
  File "/home/airflow/.local/lib/python3.12/site-packages/airflow/models/baseoperator.py", line 506, in apply_defaults
    result = func(self, **kwargs, default_args=default_args)
             ^^^^^^^^^^^^^^^^^^^^^^^^^^^^^^^^^^^^^^^^^^^^^^^
  File "/home/airflow/.local/lib/python3.12/site-packages/airflow/operators/python.py", line 222, in __init__
    super().__init__(**kwargs)
  File "/home/airflow/.local/lib/python3.12/site-packages/airflow/models/baseoperator.py", line 506, in apply_defaults
    result = func(self, **kwargs, default_args=default_args)
             ^^^^^^^^^^^^^^^^^^^^^^^^^^^^^^^^^^^^^^^^^^^^^^^
  File "/home/airflow/.local/lib/python3.12/site-packages/airflow/models/baseoperator.py", line 957, in __init__
    raise AirflowException(
airflow.exceptions.AirflowException: Invalid arguments were passed to PythonOperator (task_id: simulate_task_1). Invalid arguments were:
**kwargs: {'piority_weight': 2}
[2025-02-08T18:08:55.368+0000] {processor.py:927} WARNING - No viable dags retrieved from /opt/airflow/dags/pools.py
[2025-02-08T18:08:55.504+0000] {processor.py:208} INFO - Processing /opt/airflow/dags/pools.py took 1.160 seconds
[2025-02-08T18:09:42.754+0000] {processor.py:186} INFO - Started process (PID=13275) to work on /opt/airflow/dags/pools.py
[2025-02-08T18:09:42.804+0000] {processor.py:914} INFO - Processing file /opt/airflow/dags/pools.py for tasks to queue
[2025-02-08T18:09:42.834+0000] {logging_mixin.py:190} INFO - [2025-02-08T18:09:42.833+0000] {dagbag.py:588} INFO - Filling up the DagBag from /opt/airflow/dags/pools.py
[2025-02-08T18:09:45.058+0000] {logging_mixin.py:190} INFO - [2025-02-08T18:09:44.467+0000] {dagbag.py:387} ERROR - Failed to import: /opt/airflow/dags/pools.py
Traceback (most recent call last):
  File "/home/airflow/.local/lib/python3.12/site-packages/airflow/models/dagbag.py", line 383, in parse
    loader.exec_module(new_module)
  File "<frozen importlib._bootstrap_external>", line 999, in exec_module
  File "<frozen importlib._bootstrap>", line 488, in _call_with_frames_removed
  File "/opt/airflow/dags/pools.py", line 28, in <module>
    simulate_task_1 = PythonOperator(
                      ^^^^^^^^^^^^^^^
  File "/home/airflow/.local/lib/python3.12/site-packages/airflow/models/baseoperator.py", line 506, in apply_defaults
    result = func(self, **kwargs, default_args=default_args)
             ^^^^^^^^^^^^^^^^^^^^^^^^^^^^^^^^^^^^^^^^^^^^^^^
  File "/home/airflow/.local/lib/python3.12/site-packages/airflow/operators/python.py", line 222, in __init__
    super().__init__(**kwargs)
  File "/home/airflow/.local/lib/python3.12/site-packages/airflow/models/baseoperator.py", line 506, in apply_defaults
    result = func(self, **kwargs, default_args=default_args)
             ^^^^^^^^^^^^^^^^^^^^^^^^^^^^^^^^^^^^^^^^^^^^^^^
  File "/home/airflow/.local/lib/python3.12/site-packages/airflow/models/baseoperator.py", line 957, in __init__
    raise AirflowException(
airflow.exceptions.AirflowException: Invalid arguments were passed to PythonOperator (task_id: simulate_task_1). Invalid arguments were:
**kwargs: {'piority_weight': 2}
[2025-02-08T18:09:45.092+0000] {processor.py:927} WARNING - No viable dags retrieved from /opt/airflow/dags/pools.py
[2025-02-08T18:09:45.317+0000] {processor.py:208} INFO - Processing /opt/airflow/dags/pools.py took 2.590 seconds
[2025-02-08T18:10:21.853+0000] {processor.py:186} INFO - Started process (PID=13311) to work on /opt/airflow/dags/pools.py
[2025-02-08T18:10:21.870+0000] {processor.py:914} INFO - Processing file /opt/airflow/dags/pools.py for tasks to queue
[2025-02-08T18:10:21.887+0000] {logging_mixin.py:190} INFO - [2025-02-08T18:10:21.886+0000] {dagbag.py:588} INFO - Filling up the DagBag from /opt/airflow/dags/pools.py
[2025-02-08T18:10:23.384+0000] {logging_mixin.py:190} INFO - [2025-02-08T18:10:22.986+0000] {dagbag.py:387} ERROR - Failed to import: /opt/airflow/dags/pools.py
Traceback (most recent call last):
  File "/home/airflow/.local/lib/python3.12/site-packages/airflow/models/dagbag.py", line 383, in parse
    loader.exec_module(new_module)
  File "<frozen importlib._bootstrap_external>", line 999, in exec_module
  File "<frozen importlib._bootstrap>", line 488, in _call_with_frames_removed
  File "/opt/airflow/dags/pools.py", line 28, in <module>
    simulate_task_1 = PythonOperator(
                      ^^^^^^^^^^^^^^^
  File "/home/airflow/.local/lib/python3.12/site-packages/airflow/models/baseoperator.py", line 506, in apply_defaults
    result = func(self, **kwargs, default_args=default_args)
             ^^^^^^^^^^^^^^^^^^^^^^^^^^^^^^^^^^^^^^^^^^^^^^^
  File "/home/airflow/.local/lib/python3.12/site-packages/airflow/operators/python.py", line 222, in __init__
    super().__init__(**kwargs)
  File "/home/airflow/.local/lib/python3.12/site-packages/airflow/models/baseoperator.py", line 506, in apply_defaults
    result = func(self, **kwargs, default_args=default_args)
             ^^^^^^^^^^^^^^^^^^^^^^^^^^^^^^^^^^^^^^^^^^^^^^^
  File "/home/airflow/.local/lib/python3.12/site-packages/airflow/models/baseoperator.py", line 957, in __init__
    raise AirflowException(
airflow.exceptions.AirflowException: Invalid arguments were passed to PythonOperator (task_id: simulate_task_1). Invalid arguments were:
**kwargs: {'piority_weight': 2}
[2025-02-08T18:10:23.439+0000] {processor.py:927} WARNING - No viable dags retrieved from /opt/airflow/dags/pools.py
[2025-02-08T18:10:23.638+0000] {processor.py:208} INFO - Processing /opt/airflow/dags/pools.py took 1.810 seconds
[2025-02-08T18:10:54.532+0000] {processor.py:186} INFO - Started process (PID=13354) to work on /opt/airflow/dags/pools.py
[2025-02-08T18:10:54.538+0000] {processor.py:914} INFO - Processing file /opt/airflow/dags/pools.py for tasks to queue
[2025-02-08T18:10:54.543+0000] {logging_mixin.py:190} INFO - [2025-02-08T18:10:54.542+0000] {dagbag.py:588} INFO - Filling up the DagBag from /opt/airflow/dags/pools.py
[2025-02-08T18:10:54.682+0000] {logging_mixin.py:190} INFO - [2025-02-08T18:10:54.662+0000] {dagbag.py:387} ERROR - Failed to import: /opt/airflow/dags/pools.py
Traceback (most recent call last):
  File "/home/airflow/.local/lib/python3.12/site-packages/airflow/models/dagbag.py", line 383, in parse
    loader.exec_module(new_module)
  File "<frozen importlib._bootstrap_external>", line 999, in exec_module
  File "<frozen importlib._bootstrap>", line 488, in _call_with_frames_removed
  File "/opt/airflow/dags/pools.py", line 28, in <module>
    simulate_task_1 = PythonOperator(
                      ^^^^^^^^^^^^^^^
  File "/home/airflow/.local/lib/python3.12/site-packages/airflow/models/baseoperator.py", line 506, in apply_defaults
    result = func(self, **kwargs, default_args=default_args)
             ^^^^^^^^^^^^^^^^^^^^^^^^^^^^^^^^^^^^^^^^^^^^^^^
  File "/home/airflow/.local/lib/python3.12/site-packages/airflow/operators/python.py", line 222, in __init__
    super().__init__(**kwargs)
  File "/home/airflow/.local/lib/python3.12/site-packages/airflow/models/baseoperator.py", line 506, in apply_defaults
    result = func(self, **kwargs, default_args=default_args)
             ^^^^^^^^^^^^^^^^^^^^^^^^^^^^^^^^^^^^^^^^^^^^^^^
  File "/home/airflow/.local/lib/python3.12/site-packages/airflow/models/baseoperator.py", line 957, in __init__
    raise AirflowException(
airflow.exceptions.AirflowException: Invalid arguments were passed to PythonOperator (task_id: simulate_task_1). Invalid arguments were:
**kwargs: {'piority_weight': 2}
[2025-02-08T18:10:54.685+0000] {processor.py:927} WARNING - No viable dags retrieved from /opt/airflow/dags/pools.py
[2025-02-08T18:10:54.835+0000] {processor.py:208} INFO - Processing /opt/airflow/dags/pools.py took 0.329 seconds
[2025-02-08T18:11:26.955+0000] {processor.py:186} INFO - Started process (PID=13403) to work on /opt/airflow/dags/pools.py
[2025-02-08T18:11:26.967+0000] {processor.py:914} INFO - Processing file /opt/airflow/dags/pools.py for tasks to queue
[2025-02-08T18:11:26.973+0000] {logging_mixin.py:190} INFO - [2025-02-08T18:11:26.972+0000] {dagbag.py:588} INFO - Filling up the DagBag from /opt/airflow/dags/pools.py
[2025-02-08T18:11:27.111+0000] {logging_mixin.py:190} INFO - [2025-02-08T18:11:27.082+0000] {dagbag.py:387} ERROR - Failed to import: /opt/airflow/dags/pools.py
Traceback (most recent call last):
  File "/home/airflow/.local/lib/python3.12/site-packages/airflow/models/dagbag.py", line 383, in parse
    loader.exec_module(new_module)
  File "<frozen importlib._bootstrap_external>", line 999, in exec_module
  File "<frozen importlib._bootstrap>", line 488, in _call_with_frames_removed
  File "/opt/airflow/dags/pools.py", line 28, in <module>
    simulate_task_1 = PythonOperator(
                      ^^^^^^^^^^^^^^^
  File "/home/airflow/.local/lib/python3.12/site-packages/airflow/models/baseoperator.py", line 506, in apply_defaults
    result = func(self, **kwargs, default_args=default_args)
             ^^^^^^^^^^^^^^^^^^^^^^^^^^^^^^^^^^^^^^^^^^^^^^^
  File "/home/airflow/.local/lib/python3.12/site-packages/airflow/operators/python.py", line 222, in __init__
    super().__init__(**kwargs)
  File "/home/airflow/.local/lib/python3.12/site-packages/airflow/models/baseoperator.py", line 506, in apply_defaults
    result = func(self, **kwargs, default_args=default_args)
             ^^^^^^^^^^^^^^^^^^^^^^^^^^^^^^^^^^^^^^^^^^^^^^^
  File "/home/airflow/.local/lib/python3.12/site-packages/airflow/models/baseoperator.py", line 957, in __init__
    raise AirflowException(
airflow.exceptions.AirflowException: Invalid arguments were passed to PythonOperator (task_id: simulate_task_1). Invalid arguments were:
**kwargs: {'piority_weight': 2}
[2025-02-08T18:11:27.117+0000] {processor.py:927} WARNING - No viable dags retrieved from /opt/airflow/dags/pools.py
[2025-02-08T18:11:27.234+0000] {processor.py:208} INFO - Processing /opt/airflow/dags/pools.py took 0.331 seconds
[2025-02-08T18:12:00.014+0000] {processor.py:186} INFO - Started process (PID=13462) to work on /opt/airflow/dags/pools.py
[2025-02-08T18:12:00.019+0000] {processor.py:914} INFO - Processing file /opt/airflow/dags/pools.py for tasks to queue
[2025-02-08T18:12:00.032+0000] {logging_mixin.py:190} INFO - [2025-02-08T18:12:00.032+0000] {dagbag.py:588} INFO - Filling up the DagBag from /opt/airflow/dags/pools.py
[2025-02-08T18:12:00.225+0000] {logging_mixin.py:190} INFO - [2025-02-08T18:12:00.208+0000] {dagbag.py:387} ERROR - Failed to import: /opt/airflow/dags/pools.py
Traceback (most recent call last):
  File "/home/airflow/.local/lib/python3.12/site-packages/airflow/models/dagbag.py", line 383, in parse
    loader.exec_module(new_module)
  File "<frozen importlib._bootstrap_external>", line 999, in exec_module
  File "<frozen importlib._bootstrap>", line 488, in _call_with_frames_removed
  File "/opt/airflow/dags/pools.py", line 28, in <module>
    simulate_task_1 = PythonOperator(
                      ^^^^^^^^^^^^^^^
  File "/home/airflow/.local/lib/python3.12/site-packages/airflow/models/baseoperator.py", line 506, in apply_defaults
    result = func(self, **kwargs, default_args=default_args)
             ^^^^^^^^^^^^^^^^^^^^^^^^^^^^^^^^^^^^^^^^^^^^^^^
  File "/home/airflow/.local/lib/python3.12/site-packages/airflow/operators/python.py", line 222, in __init__
    super().__init__(**kwargs)
  File "/home/airflow/.local/lib/python3.12/site-packages/airflow/models/baseoperator.py", line 506, in apply_defaults
    result = func(self, **kwargs, default_args=default_args)
             ^^^^^^^^^^^^^^^^^^^^^^^^^^^^^^^^^^^^^^^^^^^^^^^
  File "/home/airflow/.local/lib/python3.12/site-packages/airflow/models/baseoperator.py", line 957, in __init__
    raise AirflowException(
airflow.exceptions.AirflowException: Invalid arguments were passed to PythonOperator (task_id: simulate_task_1). Invalid arguments were:
**kwargs: {'piority_weight': 2}
[2025-02-08T18:12:00.227+0000] {processor.py:927} WARNING - No viable dags retrieved from /opt/airflow/dags/pools.py
[2025-02-08T18:12:00.399+0000] {processor.py:208} INFO - Processing /opt/airflow/dags/pools.py took 0.434 seconds
[2025-02-08T18:12:36.961+0000] {processor.py:186} INFO - Started process (PID=13515) to work on /opt/airflow/dags/pools.py
[2025-02-08T18:12:36.967+0000] {processor.py:914} INFO - Processing file /opt/airflow/dags/pools.py for tasks to queue
[2025-02-08T18:12:36.972+0000] {logging_mixin.py:190} INFO - [2025-02-08T18:12:36.971+0000] {dagbag.py:588} INFO - Filling up the DagBag from /opt/airflow/dags/pools.py
[2025-02-08T18:12:37.132+0000] {logging_mixin.py:190} INFO - [2025-02-08T18:12:37.117+0000] {dagbag.py:387} ERROR - Failed to import: /opt/airflow/dags/pools.py
Traceback (most recent call last):
  File "/home/airflow/.local/lib/python3.12/site-packages/airflow/models/dagbag.py", line 383, in parse
    loader.exec_module(new_module)
  File "<frozen importlib._bootstrap_external>", line 999, in exec_module
  File "<frozen importlib._bootstrap>", line 488, in _call_with_frames_removed
  File "/opt/airflow/dags/pools.py", line 28, in <module>
    simulate_task_1 = PythonOperator(
                      ^^^^^^^^^^^^^^^
  File "/home/airflow/.local/lib/python3.12/site-packages/airflow/models/baseoperator.py", line 506, in apply_defaults
    result = func(self, **kwargs, default_args=default_args)
             ^^^^^^^^^^^^^^^^^^^^^^^^^^^^^^^^^^^^^^^^^^^^^^^
  File "/home/airflow/.local/lib/python3.12/site-packages/airflow/operators/python.py", line 222, in __init__
    super().__init__(**kwargs)
  File "/home/airflow/.local/lib/python3.12/site-packages/airflow/models/baseoperator.py", line 506, in apply_defaults
    result = func(self, **kwargs, default_args=default_args)
             ^^^^^^^^^^^^^^^^^^^^^^^^^^^^^^^^^^^^^^^^^^^^^^^
  File "/home/airflow/.local/lib/python3.12/site-packages/airflow/models/baseoperator.py", line 957, in __init__
    raise AirflowException(
airflow.exceptions.AirflowException: Invalid arguments were passed to PythonOperator (task_id: simulate_task_1). Invalid arguments were:
**kwargs: {'piority_weight': 2}
[2025-02-08T18:12:37.136+0000] {processor.py:927} WARNING - No viable dags retrieved from /opt/airflow/dags/pools.py
[2025-02-08T18:12:37.219+0000] {processor.py:208} INFO - Processing /opt/airflow/dags/pools.py took 0.310 seconds
[2025-02-08T18:13:07.789+0000] {processor.py:186} INFO - Started process (PID=13582) to work on /opt/airflow/dags/pools.py
[2025-02-08T18:13:07.791+0000] {processor.py:914} INFO - Processing file /opt/airflow/dags/pools.py for tasks to queue
[2025-02-08T18:13:07.794+0000] {logging_mixin.py:190} INFO - [2025-02-08T18:13:07.793+0000] {dagbag.py:588} INFO - Filling up the DagBag from /opt/airflow/dags/pools.py
[2025-02-08T18:13:07.857+0000] {logging_mixin.py:190} INFO - [2025-02-08T18:13:07.847+0000] {dagbag.py:387} ERROR - Failed to import: /opt/airflow/dags/pools.py
Traceback (most recent call last):
  File "/home/airflow/.local/lib/python3.12/site-packages/airflow/models/dagbag.py", line 383, in parse
    loader.exec_module(new_module)
  File "<frozen importlib._bootstrap_external>", line 999, in exec_module
  File "<frozen importlib._bootstrap>", line 488, in _call_with_frames_removed
  File "/opt/airflow/dags/pools.py", line 28, in <module>
    simulate_task_1 = PythonOperator(
                      ^^^^^^^^^^^^^^^
  File "/home/airflow/.local/lib/python3.12/site-packages/airflow/models/baseoperator.py", line 506, in apply_defaults
    result = func(self, **kwargs, default_args=default_args)
             ^^^^^^^^^^^^^^^^^^^^^^^^^^^^^^^^^^^^^^^^^^^^^^^
  File "/home/airflow/.local/lib/python3.12/site-packages/airflow/operators/python.py", line 222, in __init__
    super().__init__(**kwargs)
  File "/home/airflow/.local/lib/python3.12/site-packages/airflow/models/baseoperator.py", line 506, in apply_defaults
    result = func(self, **kwargs, default_args=default_args)
             ^^^^^^^^^^^^^^^^^^^^^^^^^^^^^^^^^^^^^^^^^^^^^^^
  File "/home/airflow/.local/lib/python3.12/site-packages/airflow/models/baseoperator.py", line 957, in __init__
    raise AirflowException(
airflow.exceptions.AirflowException: Invalid arguments were passed to PythonOperator (task_id: simulate_task_1). Invalid arguments were:
**kwargs: {'piority_weight': 2}
[2025-02-08T18:13:07.859+0000] {processor.py:927} WARNING - No viable dags retrieved from /opt/airflow/dags/pools.py
[2025-02-08T18:13:07.912+0000] {processor.py:208} INFO - Processing /opt/airflow/dags/pools.py took 0.138 seconds
[2025-02-08T18:13:38.779+0000] {processor.py:186} INFO - Started process (PID=13649) to work on /opt/airflow/dags/pools.py
[2025-02-08T18:13:38.784+0000] {processor.py:914} INFO - Processing file /opt/airflow/dags/pools.py for tasks to queue
[2025-02-08T18:13:38.788+0000] {logging_mixin.py:190} INFO - [2025-02-08T18:13:38.787+0000] {dagbag.py:588} INFO - Filling up the DagBag from /opt/airflow/dags/pools.py
[2025-02-08T18:13:38.850+0000] {logging_mixin.py:190} INFO - [2025-02-08T18:13:38.831+0000] {dagbag.py:387} ERROR - Failed to import: /opt/airflow/dags/pools.py
Traceback (most recent call last):
  File "/home/airflow/.local/lib/python3.12/site-packages/airflow/models/dagbag.py", line 383, in parse
    loader.exec_module(new_module)
  File "<frozen importlib._bootstrap_external>", line 999, in exec_module
  File "<frozen importlib._bootstrap>", line 488, in _call_with_frames_removed
  File "/opt/airflow/dags/pools.py", line 28, in <module>
    simulate_task_1 = PythonOperator(
                      ^^^^^^^^^^^^^^^
  File "/home/airflow/.local/lib/python3.12/site-packages/airflow/models/baseoperator.py", line 506, in apply_defaults
    result = func(self, **kwargs, default_args=default_args)
             ^^^^^^^^^^^^^^^^^^^^^^^^^^^^^^^^^^^^^^^^^^^^^^^
  File "/home/airflow/.local/lib/python3.12/site-packages/airflow/operators/python.py", line 222, in __init__
    super().__init__(**kwargs)
  File "/home/airflow/.local/lib/python3.12/site-packages/airflow/models/baseoperator.py", line 506, in apply_defaults
    result = func(self, **kwargs, default_args=default_args)
             ^^^^^^^^^^^^^^^^^^^^^^^^^^^^^^^^^^^^^^^^^^^^^^^
  File "/home/airflow/.local/lib/python3.12/site-packages/airflow/models/baseoperator.py", line 957, in __init__
    raise AirflowException(
airflow.exceptions.AirflowException: Invalid arguments were passed to PythonOperator (task_id: simulate_task_1). Invalid arguments were:
**kwargs: {'piority_weight': 2}
[2025-02-08T18:13:38.852+0000] {processor.py:927} WARNING - No viable dags retrieved from /opt/airflow/dags/pools.py
[2025-02-08T18:13:38.905+0000] {processor.py:208} INFO - Processing /opt/airflow/dags/pools.py took 0.156 seconds
[2025-02-08T18:14:09.225+0000] {processor.py:186} INFO - Started process (PID=13718) to work on /opt/airflow/dags/pools.py
[2025-02-08T18:14:09.227+0000] {processor.py:914} INFO - Processing file /opt/airflow/dags/pools.py for tasks to queue
[2025-02-08T18:14:09.229+0000] {logging_mixin.py:190} INFO - [2025-02-08T18:14:09.228+0000] {dagbag.py:588} INFO - Filling up the DagBag from /opt/airflow/dags/pools.py
[2025-02-08T18:14:09.279+0000] {logging_mixin.py:190} INFO - [2025-02-08T18:14:09.270+0000] {dagbag.py:387} ERROR - Failed to import: /opt/airflow/dags/pools.py
Traceback (most recent call last):
  File "/home/airflow/.local/lib/python3.12/site-packages/airflow/models/dagbag.py", line 383, in parse
    loader.exec_module(new_module)
  File "<frozen importlib._bootstrap_external>", line 999, in exec_module
  File "<frozen importlib._bootstrap>", line 488, in _call_with_frames_removed
  File "/opt/airflow/dags/pools.py", line 28, in <module>
    simulate_task_1 = PythonOperator(
                      ^^^^^^^^^^^^^^^
  File "/home/airflow/.local/lib/python3.12/site-packages/airflow/models/baseoperator.py", line 506, in apply_defaults
    result = func(self, **kwargs, default_args=default_args)
             ^^^^^^^^^^^^^^^^^^^^^^^^^^^^^^^^^^^^^^^^^^^^^^^
  File "/home/airflow/.local/lib/python3.12/site-packages/airflow/operators/python.py", line 222, in __init__
    super().__init__(**kwargs)
  File "/home/airflow/.local/lib/python3.12/site-packages/airflow/models/baseoperator.py", line 506, in apply_defaults
    result = func(self, **kwargs, default_args=default_args)
             ^^^^^^^^^^^^^^^^^^^^^^^^^^^^^^^^^^^^^^^^^^^^^^^
  File "/home/airflow/.local/lib/python3.12/site-packages/airflow/models/baseoperator.py", line 957, in __init__
    raise AirflowException(
airflow.exceptions.AirflowException: Invalid arguments were passed to PythonOperator (task_id: simulate_task_1). Invalid arguments were:
**kwargs: {'piority_weight': 2}
[2025-02-08T18:14:09.281+0000] {processor.py:927} WARNING - No viable dags retrieved from /opt/airflow/dags/pools.py
[2025-02-08T18:14:09.330+0000] {processor.py:208} INFO - Processing /opt/airflow/dags/pools.py took 0.117 seconds
[2025-02-08T18:14:55.625+0000] {processor.py:186} INFO - Started process (PID=13789) to work on /opt/airflow/dags/pools.py
[2025-02-08T18:14:55.630+0000] {processor.py:914} INFO - Processing file /opt/airflow/dags/pools.py for tasks to queue
[2025-02-08T18:14:55.644+0000] {logging_mixin.py:190} INFO - [2025-02-08T18:14:55.643+0000] {dagbag.py:588} INFO - Filling up the DagBag from /opt/airflow/dags/pools.py
[2025-02-08T18:14:55.915+0000] {logging_mixin.py:190} INFO - [2025-02-08T18:14:55.893+0000] {dagbag.py:387} ERROR - Failed to import: /opt/airflow/dags/pools.py
Traceback (most recent call last):
  File "/home/airflow/.local/lib/python3.12/site-packages/airflow/models/dagbag.py", line 383, in parse
    loader.exec_module(new_module)
  File "<frozen importlib._bootstrap_external>", line 999, in exec_module
  File "<frozen importlib._bootstrap>", line 488, in _call_with_frames_removed
  File "/opt/airflow/dags/pools.py", line 28, in <module>
    simulate_task_1 = PythonOperator(
                      ^^^^^^^^^^^^^^^
  File "/home/airflow/.local/lib/python3.12/site-packages/airflow/models/baseoperator.py", line 506, in apply_defaults
    result = func(self, **kwargs, default_args=default_args)
             ^^^^^^^^^^^^^^^^^^^^^^^^^^^^^^^^^^^^^^^^^^^^^^^
  File "/home/airflow/.local/lib/python3.12/site-packages/airflow/operators/python.py", line 222, in __init__
    super().__init__(**kwargs)
  File "/home/airflow/.local/lib/python3.12/site-packages/airflow/models/baseoperator.py", line 506, in apply_defaults
    result = func(self, **kwargs, default_args=default_args)
             ^^^^^^^^^^^^^^^^^^^^^^^^^^^^^^^^^^^^^^^^^^^^^^^
  File "/home/airflow/.local/lib/python3.12/site-packages/airflow/models/baseoperator.py", line 957, in __init__
    raise AirflowException(
airflow.exceptions.AirflowException: Invalid arguments were passed to PythonOperator (task_id: simulate_task_1). Invalid arguments were:
**kwargs: {'piority_weight': 2}
[2025-02-08T18:14:55.921+0000] {processor.py:927} WARNING - No viable dags retrieved from /opt/airflow/dags/pools.py
[2025-02-08T18:14:56.021+0000] {processor.py:208} INFO - Processing /opt/airflow/dags/pools.py took 0.439 seconds
[2025-02-08T18:15:27.003+0000] {processor.py:186} INFO - Started process (PID=13856) to work on /opt/airflow/dags/pools.py
[2025-02-08T18:15:27.043+0000] {processor.py:914} INFO - Processing file /opt/airflow/dags/pools.py for tasks to queue
[2025-02-08T18:15:27.055+0000] {logging_mixin.py:190} INFO - [2025-02-08T18:15:27.054+0000] {dagbag.py:588} INFO - Filling up the DagBag from /opt/airflow/dags/pools.py
[2025-02-08T18:15:27.243+0000] {logging_mixin.py:190} INFO - [2025-02-08T18:15:27.188+0000] {dagbag.py:387} ERROR - Failed to import: /opt/airflow/dags/pools.py
Traceback (most recent call last):
  File "/home/airflow/.local/lib/python3.12/site-packages/airflow/models/dagbag.py", line 383, in parse
    loader.exec_module(new_module)
  File "<frozen importlib._bootstrap_external>", line 999, in exec_module
  File "<frozen importlib._bootstrap>", line 488, in _call_with_frames_removed
  File "/opt/airflow/dags/pools.py", line 28, in <module>
    simulate_task_1 = PythonOperator(
                      ^^^^^^^^^^^^^^^
  File "/home/airflow/.local/lib/python3.12/site-packages/airflow/models/baseoperator.py", line 506, in apply_defaults
    result = func(self, **kwargs, default_args=default_args)
             ^^^^^^^^^^^^^^^^^^^^^^^^^^^^^^^^^^^^^^^^^^^^^^^
  File "/home/airflow/.local/lib/python3.12/site-packages/airflow/operators/python.py", line 222, in __init__
    super().__init__(**kwargs)
  File "/home/airflow/.local/lib/python3.12/site-packages/airflow/models/baseoperator.py", line 506, in apply_defaults
    result = func(self, **kwargs, default_args=default_args)
             ^^^^^^^^^^^^^^^^^^^^^^^^^^^^^^^^^^^^^^^^^^^^^^^
  File "/home/airflow/.local/lib/python3.12/site-packages/airflow/models/baseoperator.py", line 957, in __init__
    raise AirflowException(
airflow.exceptions.AirflowException: Invalid arguments were passed to PythonOperator (task_id: simulate_task_1). Invalid arguments were:
**kwargs: {'piority_weight': 2}
[2025-02-08T18:15:27.248+0000] {processor.py:927} WARNING - No viable dags retrieved from /opt/airflow/dags/pools.py
[2025-02-08T18:15:27.389+0000] {processor.py:208} INFO - Processing /opt/airflow/dags/pools.py took 0.439 seconds
[2025-02-08T18:15:57.616+0000] {processor.py:186} INFO - Started process (PID=13924) to work on /opt/airflow/dags/pools.py
[2025-02-08T18:15:57.621+0000] {processor.py:914} INFO - Processing file /opt/airflow/dags/pools.py for tasks to queue
[2025-02-08T18:15:57.632+0000] {logging_mixin.py:190} INFO - [2025-02-08T18:15:57.631+0000] {dagbag.py:588} INFO - Filling up the DagBag from /opt/airflow/dags/pools.py
[2025-02-08T18:15:57.783+0000] {logging_mixin.py:190} INFO - [2025-02-08T18:15:57.758+0000] {dagbag.py:387} ERROR - Failed to import: /opt/airflow/dags/pools.py
Traceback (most recent call last):
  File "/home/airflow/.local/lib/python3.12/site-packages/airflow/models/dagbag.py", line 383, in parse
    loader.exec_module(new_module)
  File "<frozen importlib._bootstrap_external>", line 999, in exec_module
  File "<frozen importlib._bootstrap>", line 488, in _call_with_frames_removed
  File "/opt/airflow/dags/pools.py", line 28, in <module>
    simulate_task_1 = PythonOperator(
                      ^^^^^^^^^^^^^^^
  File "/home/airflow/.local/lib/python3.12/site-packages/airflow/models/baseoperator.py", line 506, in apply_defaults
    result = func(self, **kwargs, default_args=default_args)
             ^^^^^^^^^^^^^^^^^^^^^^^^^^^^^^^^^^^^^^^^^^^^^^^
  File "/home/airflow/.local/lib/python3.12/site-packages/airflow/operators/python.py", line 222, in __init__
    super().__init__(**kwargs)
  File "/home/airflow/.local/lib/python3.12/site-packages/airflow/models/baseoperator.py", line 506, in apply_defaults
    result = func(self, **kwargs, default_args=default_args)
             ^^^^^^^^^^^^^^^^^^^^^^^^^^^^^^^^^^^^^^^^^^^^^^^
  File "/home/airflow/.local/lib/python3.12/site-packages/airflow/models/baseoperator.py", line 957, in __init__
    raise AirflowException(
airflow.exceptions.AirflowException: Invalid arguments were passed to PythonOperator (task_id: simulate_task_1). Invalid arguments were:
**kwargs: {'piority_weight': 2}
[2025-02-08T18:15:57.787+0000] {processor.py:927} WARNING - No viable dags retrieved from /opt/airflow/dags/pools.py
[2025-02-08T18:15:57.904+0000] {processor.py:208} INFO - Processing /opt/airflow/dags/pools.py took 0.322 seconds
[2025-02-08T18:16:28.163+0000] {processor.py:186} INFO - Started process (PID=13990) to work on /opt/airflow/dags/pools.py
[2025-02-08T18:16:28.166+0000] {processor.py:914} INFO - Processing file /opt/airflow/dags/pools.py for tasks to queue
[2025-02-08T18:16:28.180+0000] {logging_mixin.py:190} INFO - [2025-02-08T18:16:28.169+0000] {dagbag.py:588} INFO - Filling up the DagBag from /opt/airflow/dags/pools.py
[2025-02-08T18:16:28.289+0000] {logging_mixin.py:190} INFO - [2025-02-08T18:16:28.255+0000] {dagbag.py:387} ERROR - Failed to import: /opt/airflow/dags/pools.py
Traceback (most recent call last):
  File "/home/airflow/.local/lib/python3.12/site-packages/airflow/models/dagbag.py", line 383, in parse
    loader.exec_module(new_module)
  File "<frozen importlib._bootstrap_external>", line 999, in exec_module
  File "<frozen importlib._bootstrap>", line 488, in _call_with_frames_removed
  File "/opt/airflow/dags/pools.py", line 28, in <module>
    simulate_task_1 = PythonOperator(
                      ^^^^^^^^^^^^^^^
  File "/home/airflow/.local/lib/python3.12/site-packages/airflow/models/baseoperator.py", line 506, in apply_defaults
    result = func(self, **kwargs, default_args=default_args)
             ^^^^^^^^^^^^^^^^^^^^^^^^^^^^^^^^^^^^^^^^^^^^^^^
  File "/home/airflow/.local/lib/python3.12/site-packages/airflow/operators/python.py", line 222, in __init__
    super().__init__(**kwargs)
  File "/home/airflow/.local/lib/python3.12/site-packages/airflow/models/baseoperator.py", line 506, in apply_defaults
    result = func(self, **kwargs, default_args=default_args)
             ^^^^^^^^^^^^^^^^^^^^^^^^^^^^^^^^^^^^^^^^^^^^^^^
  File "/home/airflow/.local/lib/python3.12/site-packages/airflow/models/baseoperator.py", line 957, in __init__
    raise AirflowException(
airflow.exceptions.AirflowException: Invalid arguments were passed to PythonOperator (task_id: simulate_task_1). Invalid arguments were:
**kwargs: {'piority_weight': 2}
[2025-02-08T18:16:28.291+0000] {processor.py:927} WARNING - No viable dags retrieved from /opt/airflow/dags/pools.py
[2025-02-08T18:16:28.401+0000] {processor.py:208} INFO - Processing /opt/airflow/dags/pools.py took 0.280 seconds
[2025-02-08T18:16:59.835+0000] {processor.py:186} INFO - Started process (PID=14055) to work on /opt/airflow/dags/pools.py
[2025-02-08T18:16:59.837+0000] {processor.py:914} INFO - Processing file /opt/airflow/dags/pools.py for tasks to queue
[2025-02-08T18:16:59.841+0000] {logging_mixin.py:190} INFO - [2025-02-08T18:16:59.839+0000] {dagbag.py:588} INFO - Filling up the DagBag from /opt/airflow/dags/pools.py
[2025-02-08T18:16:59.884+0000] {logging_mixin.py:190} INFO - [2025-02-08T18:16:59.872+0000] {dagbag.py:387} ERROR - Failed to import: /opt/airflow/dags/pools.py
Traceback (most recent call last):
  File "/home/airflow/.local/lib/python3.12/site-packages/airflow/models/dagbag.py", line 383, in parse
    loader.exec_module(new_module)
  File "<frozen importlib._bootstrap_external>", line 999, in exec_module
  File "<frozen importlib._bootstrap>", line 488, in _call_with_frames_removed
  File "/opt/airflow/dags/pools.py", line 28, in <module>
    simulate_task_1 = PythonOperator(
                      ^^^^^^^^^^^^^^^
  File "/home/airflow/.local/lib/python3.12/site-packages/airflow/models/baseoperator.py", line 506, in apply_defaults
    result = func(self, **kwargs, default_args=default_args)
             ^^^^^^^^^^^^^^^^^^^^^^^^^^^^^^^^^^^^^^^^^^^^^^^
  File "/home/airflow/.local/lib/python3.12/site-packages/airflow/operators/python.py", line 222, in __init__
    super().__init__(**kwargs)
  File "/home/airflow/.local/lib/python3.12/site-packages/airflow/models/baseoperator.py", line 506, in apply_defaults
    result = func(self, **kwargs, default_args=default_args)
             ^^^^^^^^^^^^^^^^^^^^^^^^^^^^^^^^^^^^^^^^^^^^^^^
  File "/home/airflow/.local/lib/python3.12/site-packages/airflow/models/baseoperator.py", line 957, in __init__
    raise AirflowException(
airflow.exceptions.AirflowException: Invalid arguments were passed to PythonOperator (task_id: simulate_task_1). Invalid arguments were:
**kwargs: {'piority_weight': 2}
[2025-02-08T18:16:59.895+0000] {processor.py:927} WARNING - No viable dags retrieved from /opt/airflow/dags/pools.py
[2025-02-08T18:16:59.967+0000] {processor.py:208} INFO - Processing /opt/airflow/dags/pools.py took 0.149 seconds
